Workbook

Sheet 00-راهنما
A1: راهنمای ابزار عملیاتی بازنگری مدیریت IMS
A2: هلدینگ نیکان | نسخه 02 | داده واقعی نورایستا پلاستیک و سناریوهای فرضی جداگانه | ابتدا تنظیمات و دامنه را تکمیل کنید.
A7: مرحله | B7: روش استفاده | C7: محل
A8: ۱. شروع | B8: در تنظیمات شرکت، دوره، جلسه، تاریخ مبنا و نوع گزارش را انتخاب کنید. داده‌های NIPCO واقعی اما نیازمند تأییدند؛ همه داده‌های DEMO فرضی و آموزشی‌اند. | C8: 01، 17، 18
A9: ۲. دامنه | B9: نسخه جاری گواهینامه، دامنه و برنامه انتقال هر شرکت را ثبت کنید. انتشار نسخه ۲۰۲۶ جایگزینی خودکار نسخه جاری شرکت یا IATF نیست. | C9: 18 و 14
A10: ۳. ورودی | B10: ورودی، سند و تحلیل مالک را یک‌بار در 03 ثبت کنید. شاخص با هدف، جهت مطلوب، مرجع هدف و اعتبار داده در 04 ثبت شود. مقدار خالی به معنای صفر نیست. | C10: 03 و 04
A11: ۴. بررسی | B11: پیشنهادهای کارشناسی را در 05 بررسی کنید. نتیجه مدیریت برای تناسب، کفایت و اثربخشی هر سیستم در 06 با شاهد و تأیید ثبت شود. | C11: 05 و 06
A12: ۵. تصمیم | B12: هر تصمیم یک شناسه پایدار دارد. رد، تعویق، درخواست بررسی و عدم نیاز به تغییر مجاز است؛ دلیل و مرجع تأیید الزامی است. شماره ردیف شناسه محسوب نمی‌شود. | C12: 07
A13: ۶. روابط | B13: برای هر ورودی یا الزام مرتبط یک ردیف در 15 ایجاد کنید. برای هر تصمیم چند اقدام در 08 قابل ثبت است. هر اقدام فقط یک تصمیم مادر دارد. | C13: 15 و 08
A14: ۷. منابع و ابلاغ | B14: برای منابع، مقدار، هزینه در صورت وجود، تصمیم و مسئول را ثبت کنید. در رد/تعویق، ریسک باقی‌مانده ثبت شود. ابلاغ OH&S در 20 ثبت گردد. | C14: 09 و 20
A15: ۸. اثربخشی | B15: پس از اجرا، شاهد و نتیجه واقعی را ثبت کنید. ارزیابی اثربخش بدون معیار، تاریخ و ارزیاب معتبر نمی‌شود. وضعیت نهایی تصمیم به تکمیل همه اقدامات وابسته است. | C15: 08، 10، 07
A16: ۹. گزارش | B16: صورت‌جلسه از بانک تصمیمات تولید می‌شود؛ هر صفحه ۲۰ ردیف دارد. تنظیمات صفحه را افزایش دهید. پیش از جلسه و گزارش پس از جلسه عنوان متفاوت دارند. | C16: 11 و 01!B8
A17: ۱۰. پوشش | B17: برای هر الزام، شناسه سابقه بررسی همان جلسه را در کنترل انطباق ثبت کنید. خالی‌بودن سابقه، شاهد ناقص و نسخه تأییدنشده آشکار می‌ماند. | C17: 13
A18: ۱۱. توسعه | B18: جداول ساختاریافته با ردیف‌های آماده ارائه شده‌اند. ردیف آماده را پر کنید؛ پس از اتمام، ردیف جدول را همراه فرمول و اعتبارسنجی کپی کنید. محدوده کنترل‌ها تا ردیف 1007 است؛ پیش از عبور آن را توسعه دهید. | C18: همه بانک‌ها
... A43: فهرست | B43: 20-ابلاغ نتایج | C43: کلیک برای رفتن به کاربرگ

Sheet 01-تنظیمات
A1: تنظیمات انتخاب گزارش
A3: شرکت گزارش | B3: NIPCO | C3: برای هلدینگ «همه واقعی»؛ نمونه‌ها از آن حذف می‌شوند
A4: دوره گزارش | B4: P-BASE | C4: برای چند دوره «همه»؛ گزارش پس از جلسه از شناسه جلسه استفاده می‌کند
A5: شناسه جلسه | B5: MR-NIPCO-BASE | C5: فقط جلسه انتخاب‌شده در صورت‌جلسه نمایش می‌یابد
A6: تاریخ مبنای کنترل | B6: 46314 | C6: تاریخ واقعی Excel؛ امروز به‌صورت ثابت برای گزارش قابل تکرار
A7: نوع گزارش | B7: پیش از جلسه | C7: «پس از جلسه» بدون تأیید جلسه، خروجی مصوب ایجاد نمی‌کند
A8: بخش صورت‌جلسه | B8: 1 | C8: هر بخش ۲۰ تصمیم؛ برای ادامه، شماره بخش را افزایش دهید. هر بخش ممکن است چند صفحه چاپی شود.
A10: کد شرکت | B10: نام شرکت | C10: نوع داده | D10: وضعیت
A11: NIPCO | B11: نورایستا پلاستیک | C11: واقعی | D11: شناخته‌شده از اسناد
A12: DEMO | B12: شرکت فرضی آموزشی | C12: فرضی | D12: از گزارش هلدینگ واقعی حذف می‌شود
A13: همه واقعی | B13: تجمیع هلدینگ نیکان | C13: واقعی | D13: فقط رکوردهای غیر DE​MO
A14: راهنما | B14: شرکت‌های دیگر را با کد پایدار به فهرست و دامنه اضافه کنید. | C14: مرجع | D14: نام زیرمجموعه نامعلوم ساخته نشده است
A17: فرآیند | B17: گروه | C17: سیستم | D17: کاربرد
A18: مدیریت / تضمین کیفیت | B18: مدیریتی | C18: IMS | D18: مشترک
A19: تولید / مهندسی / لجستیک | B19: اصلی | C19: QMS / IATF | D19: حسب دامنه شرکت
A20: خرید / انبار | B20: اصلی / پشتیبانی | C20: IMS | D20: حسب فرآیند
A21: منابع انسانی / مالی / IT | B21: پشتیبانی | C21: IMS | D21: حسب فرآیند
A22: محیط‌زیست / ایمنی / بهداشت | B22: پشتیبانی | C22: EMS / OHS | D22: حسب دامنه
A23: دوره جدید | B23: یک جلسه و شناسه دوره جدید ایجاد کنید؛ ردیف‌های تاریخی را حفظ کنید. | C23: راهنما | D23: کپی ردیف ورودی به دوره جدید با شناسه جدید و حذف تأیید قبلی
... A32: تطبیق 9001 / IATF | B32: معادل‌سازی خودکار انجام نشده | C32: انتقال باید با مرجع گواهی‌دهنده و ابلاغ رسمی کنترل شود | D32: 18-دامنه استانداردها

Sheet 02-ماتریس الزامات
A1: ماتریس الزامات بازنگری مدیریت
A2: این ماتریس دامنه بند ۹.۳ و الزامات تکمیلی آن را پوشش می‌دهد، نه تمام استانداردها. متن کامل مجاز نسخه‌های ۲۰۲۶ در دسترس نبود؛ تطبیق شماره اجزا و شرایط انتقال شرکت باز است.
A7: شناسه الزام | B7: سیستم | C7: ویرایش مبنا | D7: بند | E7: نوع | F7: خلاصه موضوع الزام | G7: محل ثبت | H7: شواهد موردنیاز | I7: روش کنترل | J7: محدودیت / وضعیت نسخه
A8: Q-I1 | B8: QMS | C8: 2015 / 2026؛ تطبیق تفصیلی باز | D8: 9.3.2 | E8: ورودی | F8: اقدامات قبلی | G8: R03 | H8: داده معتبر دوره و تحلیل مالک؛ اصل گزارش در سیستم تضمین | I8: کنترل جلسه، دامنه، شاهد، نتیجه و مرجع تأیید در 13؛ ردیف خالی تأیید نیست | J8: مبنای موضوعی؛ نسخه جاری شرکت و متن مجاز باید تأیید شود
A9: Q-I2 | B9: QMS | C9: 2015 / 2026؛ تطبیق تفصیلی باز | D9: 9.3.2 | E9: ورودی | F9: تغییرات داخلی و خارجی | G9: R04 | H9: داده معتبر دوره و تحلیل مالک؛ اصل گزارش در سیستم تضمین | I9: کنترل جلسه، دامنه، شاهد، نتیجه و مرجع تأیید در 13؛ ردیف خالی تأیید نیست | J9: مبنای موضوعی؛ نسخه جاری شرکت و متن مجاز باید تأیید شود
A10: Q-I3 | B10: QMS | C10: 2015 / 2026؛ تطبیق تفصیلی باز | D10: 9.3.2 | E10: ورودی | F10: نیازها و انتظارات ذی‌نفعان | G10: R06 | H10: داده معتبر دوره و تحلیل مالک؛ اصل گزارش در سیستم تضمین | I10: کنترل جلسه، دامنه، شاهد، نتیجه و مرجع تأیید در 13؛ ردیف خالی تأیید نیست | J10: مبنای موضوعی؛ نسخه جاری شرکت و متن مجاز باید تأیید شود
A11: Q-I4 | B11: QMS | C11: 2015 / 2026؛ تطبیق تفصیلی باز | D11: 9.3.2 | E11: ورودی | F11: اهداف و خط‌مشی | G11: R07 | H11: داده معتبر دوره و تحلیل مالک؛ اصل گزارش در سیستم تضمین | I11: کنترل جلسه، دامنه، شاهد، نتیجه و مرجع تأیید در 13؛ ردیف خالی تأیید نیست | J11: مبنای موضوعی؛ نسخه جاری شرکت و متن مجاز باید تأیید شود
A12: Q-I5 | B12: QMS | C12: 2015 / 2026؛ تطبیق تفصیلی باز | D12: 9.3.2 | E12: ورودی | F12: عملکرد فرآیند و محصول | G12: R07 | H12: داده معتبر دوره و تحلیل مالک؛ اصل گزارش در سیستم تضمین | I12: کنترل جلسه، دامنه، شاهد، نتیجه و مرجع تأیید در 13؛ ردیف خالی تأیید نیست | J12: مبنای موضوعی؛ نسخه جاری شرکت و متن مجاز باید تأیید شود
A13: Q-I6 | B13: QMS | C13: 2015 / 2026؛ تطبیق تفصیلی باز | D13: 9.3.2 | E13: ورودی | F13: رضایت و شکایت مشتری | G13: R11 | H13: داده معتبر دوره و تحلیل مالک؛ اصل گزارش در سیستم تضمین | I13: کنترل جلسه، دامنه، شاهد، نتیجه و مرجع تأیید در 13؛ ردیف خالی تأیید نیست | J13: مبنای موضوعی؛ نسخه جاری شرکت و متن مجاز باید تأیید شود
A14: Q-I7 | B14: QMS | C14: 2015 / 2026؛ تطبیق تفصیلی باز | D14: 9.3.2 | E14: ورودی | F14: تأمین‌کنندگان | G14: R23 | H14: داده معتبر دوره و تحلیل مالک؛ اصل گزارش در سیستم تضمین | I14: کنترل جلسه، دامنه، شاهد، نتیجه و مرجع تأیید در 13؛ ردیف خالی تأیید نیست | J14: مبنای موضوعی؛ نسخه جاری شرکت و متن مجاز باید تأیید شود
A15: Q-I8 | B15: QMS | C15: 2015 / 2026؛ تطبیق تفصیلی باز | D15: 9.3.2 | E15: ورودی | F15: ممیزی‌ها | G15: R08 | H15: داده معتبر دوره و تحلیل مالک؛ اصل گزارش در سیستم تضمین | I15: کنترل جلسه، دامنه، شاهد، نتیجه و مرجع تأیید در 13؛ ردیف خالی تأیید نیست | J15: مبنای موضوعی؛ نسخه جاری شرکت و متن مجاز باید تأیید شود
A16: Q-I9 | B16: QMS | C16: 2015 / 2026؛ تطبیق تفصیلی باز | D16: 9.3.2 | E16: ورودی | F16: عدم‌انطباق و اقدام اصلاحی | G16: R10 | H16: داده معتبر دوره و تحلیل مالک؛ اصل گزارش در سیستم تضمین | I16: کنترل جلسه، دامنه، شاهد، نتیجه و مرجع تأیید در 13؛ ردیف خالی تأیید نیست | J16: مبنای موضوعی؛ نسخه جاری شرکت و متن مجاز باید تأیید شود
A17: Q-I10 | B17: QMS | C17: 2015 / 2026؛ تطبیق تفصیلی باز | D17: 9.3.2 | E17: ورودی | F17: پایش و اندازه‌گیری | G17: R12 | H17: داده معتبر دوره و تحلیل مالک؛ اصل گزارش در سیستم تضمین | I17: کنترل جلسه، دامنه، شاهد، نتیجه و مرجع تأیید در 13؛ ردیف خالی تأیید نیست | J17: مبنای موضوعی؛ نسخه جاری شرکت و متن مجاز باید تأیید شود
A18: Q-I11 | B18: QMS | C18: 2015 / 2026؛ تطبیق تفصیلی باز | D18: 9.3.2 | E18: ورودی | F18: کفایت منابع | G18: R17 | H18: داده معتبر دوره و تحلیل مالک؛ اصل گزارش در سیستم تضمین | I18: کنترل جلسه، دامنه، شاهد، نتیجه و مرجع تأیید در 13؛ ردیف خالی تأیید نیست | J18: مبنای موضوعی؛ نسخه جاری شرکت و متن مجاز باید تأیید شود
... A81: OHS-O9 | B81: OHS | C81: 45001:2018 + Amd1:2024 | D81: 9.3 | E81: خروجی | F81: نگهداری شواهد نتایج | G81: 06 و 07 و 09 و 11 | H81: نظر مدیریت، توجیه، شاهد و تأیید؛ حسب نیاز اقدام/ابلاغ | I81: کنترل جلسه، دامنه، شاهد، نتیجه و مرجع تأیید در 13؛ ردیف خالی تأیید نیست | J81: مبنای موضوعی؛ نسخه جاری شرکت و متن مجاز باید تأیید شود

Sheet 03-ورودی‌های بازنگری
A1: ورودی‌های مستند و تحلیل
A2: اطلاعات واقعی از دو گزارش مبنا نقل شده‌اند و هنوز با فایل پایش تطبیق نشده‌اند. وضعیت بررسی مدیریت برای داده واقعی خالی/بررسی‌نشده است.
A7: شناسه ورودی | B7: شرکت | C7: دوره | D7: جلسه | E7: نوع داده | F7: فرآیند | G7: سیستم | H7: موضوع | I7: مرجع اصلی | J7: تحلیل کارشناسی | K7: پیشنهاد پیش از جلسه | L7: شناسه شاهد | M7: وضعیت بررسی | N7: ریسک | O7: نتیجه بررسی مدیریت | P7: بررسی‌کننده | Q7: مرجع تأیید | R7: کنترل ورودی
A8: IN-R01 | B8: NIPCO | C8: P-BASE | D8: MR-NIPCO-BASE | E8: واقعی؛ نیازمند تأیید | F8: دامنه و زمان‌بندی | G8: IMS | H8: دامنه و زمان‌بندی | I8: توضیح کاربر؛ هر دو فایل، 1!O1 | J8: بازنگری مدیریت به‌صورت سالانه، از مرداد تا مرداد و پس از برگزاری مجمع عمومی انجام می‌شود. دامنه شامل کیفیت، الزامات صنعت خودرو، محیط‌زیست، ایمنی و بهداشت شغلی و فرآیندهای لجستیکی مرتبط است. | K8: مرز روزانه دوره، سال ابتدا و انتها و ویرایش استانداردها باید در مشخصات گزارش تکمیل شود. | L8: DOC-SOURCE | M8: بررسی نشده | N8: نیازمند تعیین | R8: =IF(A8="","",IF(NOT(AND(COUNTIFS('03-ورودی‌های بازنگری'!$A$8:$A$1007,A8)=1,AND(COUNTIFS('17-جلسات و دوره‌ها'!$A$8:$A$1007,D8)=1,IFERROR(INDEX('17-جلسات و دوره‌ها'!$B$8:$B$1007,MATCH(D8,'17-جلسات و دوره‌ها'!$A$8:$A$1007,0)),"")=B8,IFERROR(INDEX('17-جلسات و دوره‌ها'!$C$8:$C$1007,MATCH(D8,'17-جلسات و دوره‌ها'!$A$8:$A$1007,0)),"")=C8))),"شناسه یا جلسه نامعتبر",IF(AND(M8="بررسی شد",J8<>"",O8<>"",P8<>"",Q8<>"",AND(COUNTIFS('14-مستندات و پیوست‌ها'!$A$8:$A$1007,L8)=1,IFERROR(INDEX('14-مستندات و پیوست‌ها'!$B$8:$B$1007,MATCH(L8,'14-مستندات و پیوست‌ها'!$A$8:$A$1007,0)),"")=B8,OR(IFERROR(INDEX('14-مستندات و پیوست‌ها'!$H$8:$H$1007,MATCH(L8,'14-مستندات و پیوست‌ها'!$A$8:$A$1007,0)),"")="دریافت شده",IFERROR(INDEX('14-مستندات و پیوست‌ها'!$H$8:$H$1007,MATCH(L8,'14-مستندات و پیوست‌ها'!$A$8:$A$1007,0)),"")="فرضی"))),"معتبر","بررسی یا شاهد ناقص"))) -> بررسی یا شاهد ناقص
A9: IN-R02 | B9: NIPCO | C9: P-BASE | D9: MR-NIPCO-BASE | E9: واقعی؛ نیازمند تأیید | F9: مرجع داده و سوابق | G9: IMS | H9: مرجع داده و سوابق | I9: توضیح کاربر | J9: مرجع معتبر شاخص‌ها، فایل پایش شاخص‌هاست. سوابق ممیزی، پایش و پیوست‌ها در سیستم تضمین کیفیت نگهداری می‌شوند. اعداد این نسخه از گزارش‌های موجود نقل شده و هنوز با مرجع پایش تطبیق نشده‌اند. | K9: برای هر ادعا شناسه، تاریخ، نسخه و محل بازیابی شاهد درج شود. | L9: DOC-SOURCE | M9: بررسی نشده | N9: نیازمند تعیین | R9: =IF(A9="","",IF(NOT(AND(COUNTIFS('03-ورودی‌های بازنگری'!$A$8:$A$1007,A9)=1,AND(COUNTIFS('17-جلسات و دوره‌ها'!$A$8:$A$1007,D9)=1,IFERROR(INDEX('17-جلسات و دوره‌ها'!$B$8:$B$1007,MATCH(D9,'17-جلسات و دوره‌ها'!$A$8:$A$1007,0)),"")=B9,IFERROR(INDEX('17-جلسات و دوره‌ها'!$C$8:$C$1007,MATCH(D9,'17-جلسات و دوره‌ها'!$A$8:$A$1007,0)),"")=C9))),"شناسه یا جلسه نامعتبر",IF(AND(M9="بررسی شد",J9<>"",O9<>"",P9<>"",Q9<>"",AND(COUNTIFS('14-مستندات و پیوست‌ها'!$A$8:$A$1007,L9)=1,IFERROR(INDEX('14-مستندات و پیوست‌ها'!$B$8:$B$1007,MATCH(L9,'14-مستندات و پیوست‌ها'!$A$8:$A$1007,0)),"")=B9,OR(IFERROR(INDEX('14-مستندات و پیوست‌ها'!$H$8:$H$1007,MATCH(L9,'14-مستندات و پیوست‌ها'!$A$8:$A$1007,0)),"")="دریافت شده",IFERROR(INDEX('14-مستندات و پیوست‌ها'!$H$8:$H$1007,MATCH(L9,'14-مستندات و پیوست‌ها'!$A$8:$A$1007,0)),"")="فرضی"))),"معتبر","بررسی یا شاهد ناقص"))) -> بررسی یا شاهد ناقص
A10: IN-R03 | B10: NIPCO | C10: P-BASE | D10: MR-NIPCO-BASE | E10: واقعی؛ نیازمند تأیید | F10: پیگیری بازنگری قبلی | G10: IMS | H10: پیگیری بازنگری قبلی | I10: HSE 1!C4:O6؛ LOG 1!C4:O12؛ 1 (2)!C4:O12 | J10: موضوعات مشترک شامل استقرار IMS، توسعه فضای انبارش، ساخت پالت، آموزش و اصلاح مستندات است. در گزارش لجستیک راه‌اندازی جرثقیل سقفی و نصب پرس ۵۰۰ تن انجام‌شده اعلام شده است. وضعیت گواهینامه IMS در بخش‌های مختلف به‌صورت انعقاد قرارداد و اخذ گواهینامه آمده است. | K10: وضعیت جاری هر مصوبه، شاهد خاتمه و اثربخشی ثبت شود؛ ادعای اخذ گواهینامه با سابقه سیستم تضمین تطبیق یابد. | L10: DOC-SOURCE | M10: بررسی نشده | N10: نیازمند تعیین | R10: =IF(A10="","",IF(NOT(AND(COUNTIFS('03-ورودی‌های بازنگری'!$A$8:$A$1007,A10)=1,AND(COUNTIFS('17-جلسات و دوره‌ها'!$A$8:$A$1007,D10)=1,IFERROR(INDEX('17-جلسات و دوره‌ها'!$B$8:$B$1007,MATCH(D10,'17-جلسات و دوره‌ها'!$A$8:$A$1007,0)),"")=B10,IFERROR(INDEX('17-جلسات و دوره‌ها'!$C$8:$C$1007,MATCH(D10,'17-جلسات و دوره‌ها'!$A$8:$A$1007,0)),"")=C10))),"شناسه یا جلسه نامعتبر",IF(AND(M10="بررسی شد",J10<>"",O10<>"",P10<>"",Q10<>"",AND(COUNTIFS('14-مستندات و پیوست‌ها'!$A$8:$A$1007,L10)=1,IFERROR(INDEX('14-مستندات و پیوست‌ها'!$B$8:$B$1007,MATCH(L10,'14-مستندات و پیوست‌ها'!$A$8:$A$1007,0)),"")=B10,OR(IFERROR(INDEX('14-مستندات و پیوست‌ها'!$H$8:$H$1007,MATCH(L10,'14-مستندات و پیوست‌ها'!$A$8:$A$1007,0)),"")="دریافت شده",IFERROR(INDEX('14-مستندات و پیوست‌ها'!$H$8:$H$1007,MATCH(L10,'14-مستندات و پیوست‌ها'!$A$8:$A$1007,0)),"")="فرضی"))),"معتبر","بررسی یا شاهد ناقص"))) -> بررسی یا شاهد ناقص
A11: IN-R04 | B11: NIPCO | C11: P-BASE | D11: MR-NIPCO-BASE | E11: واقعی؛ نیازمند تأیید | F11: تغییرات داخلی و توسعه فضا | G11: IMS | H11: تغییرات داخلی و توسعه فضا | I11: LOG 1!C12؛ 8-9!C24؛ 17!C17؛ HSE 8-9!C15:C37 | J11: الحاق فضای ایمن ایستاالکتریک، کمبود فضای انبار و نیروی انسانی و تغییر جانمایی، موضوعات مشترک کیفیت، لجستیک و HSE هستند. کمبود ۶۲۳ مترمربع در گزارش لجستیک و کمبود ۷۰۰ مترمربع انبار نیم‌ساخته سالن ۲ ذکر شده؛ دامنه این دو مقدار متفاوت یا نیازمند تفکیک است. | K11: یک برنامه مصوب توسعه فضا همراه با کنترل‌های موقت ایمنی، انبارش و جریان مواد تنظیم شود. مهلت‌های متعارض اصلاح شوند. | L11: DOC-SOURCE | M11: بررسی نشده | N11: نیازمند تعیین | R11: =IF(A11="","",IF(NOT(AND(COUNTIFS('03-ورودی‌های بازنگری'!$A$8:$A$1007,A11)=1,AND(COUNTIFS('17-جلسات و دوره‌ها'!$A$8:$A$1007,D11)=1,IFERROR(INDEX('17-جلسات و دوره‌ها'!$B$8:$B$1007,MATCH(D11,'17-جلسات و دوره‌ها'!$A$8:$A$1007,0)),"")=B11,IFERROR(INDEX('17-جلسات و دوره‌ها'!$C$8:$C$1007,MATCH(D11,'17-جلسات و دوره‌ها'!$A$8:$A$1007,0)),"")=C11))),"شناسه یا جلسه نامعتبر",IF(AND(M11="بررسی شد",J11<>"",O11<>"",P11<>"",Q11<>"",AND(COUNTIFS('14-مستندات و پیوست‌ها'!$A$8:$A$1007,L11)=1,IFERROR(INDEX('14-مستندات و پیوست‌ها'!$B$8:$B$1007,MATCH(L11,'14-مستندات و پیوست‌ها'!$A$8:$A$1007,0)),"")=B11,OR(IFERROR(INDEX('14-مستندات و پیوست‌ها'!$H$8:$H$1007,MATCH(L11,'14-مستندات و پیوست‌ها'!$A$8:$A$1007,0)),"")="دریافت شده",IFERROR(INDEX('14-مستندات و پیوست‌ها'!$H$8:$H$1007,MATCH(L11,'14-مستندات و پیوست‌ها'!$A$8:$A$1007,0)),"")="فرضی"))),"معتبر","بررسی یا شاهد ناقص"))) -> بررسی یا شاهد ناقص
A12: IN-R05 | B12: NIPCO | C12: P-BASE | D12: MR-NIPCO-BASE | E12: واقعی؛ نیازمند تأیید | F12: تغییرات بیرونی و بازار | G12: IMS | H12: تغییرات بیرونی و بازار | I12: LOG 1!C16:O20؛ 8-9!C29:O32؛ 19!C8 | J12: در اسناد، محدودیت تأمین و نقدینگی، تأخیر پرداخت مشتریان، حذف برخی خودروها، ناپایداری منطقه و محدودیت سوخت حمل‌ونقل مطرح شده است. توسعه فروش بازار آزاد از طریق نورایستا خراسان و جذب پروژه‌های جدید به‌عنوان پاسخ معرفی شده‌اند. | K12: اثر هر تغییر بر کیفیت، تحویل، محیط‌زیست و ایمنی به‌صورت مشخص ارزیابی و مالک اقدام تعیین شود. | L12: DOC-SOURCE | M12: بررسی نشده | N12: نیازمند تعیین | R12: =IF(A12="","",IF(NOT(AND(COUNTIFS('03-ورودی‌های بازنگری'!$A$8:$A$1007,A12)=1,AND(COUNTIFS('17-جلسات و دوره‌ها'!$A$8:$A$1007,D12)=1,IFERROR(INDEX('17-جلسات و دوره‌ها'!$B$8:$B$1007,MATCH(D12,'17-جلسات و دوره‌ها'!$A$8:$A$1007,0)),"")=B12,IFERROR(INDEX('17-جلسات و دوره‌ها'!$C$8:$C$1007,MATCH(D12,'17-جلسات و دوره‌ها'!$A$8:$A$1007,0)),"")=C12))),"شناسه یا جلسه نامعتبر",IF(AND(M12="بررسی شد",J12<>"",O12<>"",P12<>"",Q12<>"",AND(COUNTIFS('14-مستندات و پیوست‌ها'!$A$8:$A$1007,L12)=1,IFERROR(INDEX('14-مستندات و پیوست‌ها'!$B$8:$B$1007,MATCH(L12,'14-مستندات و پیوست‌ها'!$A$8:$A$1007,0)),"")=B12,OR(IFERROR(INDEX('14-مستندات و پیوست‌ها'!$H$8:$H$1007,MATCH(L12,'14-مستندات و پیوست‌ها'!$A$8:$A$1007,0)),"")="دریافت شده",IFERROR(INDEX('14-مستندات و پیوست‌ها'!$H$8:$H$1007,MATCH(L12,'14-مستندات و پیوست‌ها'!$A$8:$A$1007,0)),"")="فرضی"))),"معتبر","بررسی یا شاهد ناقص"))) -> بررسی یا شاهد ناقص
A13: IN-R06 | B13: NIPCO | C13: P-BASE | D13: MR-NIPCO-BASE | E13: واقعی؛ نیازمند تأیید | F13: مشتریان و ذی‌نفعان | G13: IMS | H13: مشتریان و ذی‌نفعان | I13: LOG 1!C21:F27؛ 1 (2)!C23:C27؛ HSE 1!B20:F30 | J13: امتیازهای مشتریان، سهامداران، کارکنان و مراجع قانونی در دو گزارش درج شده‌اند. واگذاری ۳۰۰ سهم به هر یک از کارکنان و تحقق تعهدات به سهامداران در متن منبع گزارش شده است؛ این ادعاها مستقلاً تصدیق نشده‌اند. | K13: مراجع قانونی در گروه ذی‌نفعان/تعهدات انطباق طبقه‌بندی شوند. روش محاسبه رضایت و دوره امتیازها تکمیل شود. | L13: DOC-SOURCE | M13: بررسی نشده | N13: نیازمند تعیین | R13: =IF(A13="","",IF(NOT(AND(COUNTIFS('03-ورودی‌های بازنگری'!$A$8:$A$1007,A13)=1,AND(COUNTIFS('17-جلسات و دوره‌ها'!$A$8:$A$1007,D13)=1,IFERROR(INDEX('17-جلسات و دوره‌ها'!$B$8:$B$1007,MATCH(D13,'17-جلسات و دوره‌ها'!$A$8:$A$1007,0)),"")=B13,IFERROR(INDEX('17-جلسات و دوره‌ها'!$C$8:$C$1007,MATCH(D13,'17-جلسات و دوره‌ها'!$A$8:$A$1007,0)),"")=C13))),"شناسه یا جلسه نامعتبر",IF(AND(M13="بررسی شد",J13<>"",O13<>"",P13<>"",Q13<>"",AND(COUNTIFS('14-مستندات و پیوست‌ها'!$A$8:$A$1007,L13)=1,IFERROR(INDEX('14-مستندات و پیوست‌ها'!$B$8:$B$1007,MATCH(L13,'14-مستندات و پیوست‌ها'!$A$8:$A$1007,0)),"")=B13,OR(IFERROR(INDEX('14-مستندات و پیوست‌ها'!$H$8:$H$1007,MATCH(L13,'14-مستندات و پیوست‌ها'!$A$8:$A$1007,0)),"")="دریافت شده",IFERROR(INDEX('14-مستندات و پیوست‌ها'!$H$8:$H$1007,MATCH(L13,'14-مستندات و پیوست‌ها'!$A$8:$A$1007,0)),"")="فرضی"))),"معتبر","بررسی یا شاهد ناقص"))) -> بررسی یا شاهد ناقص
A14: IN-R07 | B14: NIPCO | C14: P-BASE | D14: MR-NIPCO-BASE | E14: واقعی؛ نیازمند تأیید | F14: اهداف و عملکرد فرآیندها | G14: IMS | H14: اهداف و عملکرد فرآیندها | I14: HSE 2!B5:F15؛ LOG 2-4!B5:F44؛ 10-!B8:F18 | J14: جدول یکپارچه شاخص‌ها، هدف، معیار پذیرش و مقادیر دوره قبل و جاری را همراه با اختلاف عددی نشان می‌دهد. تفاوت میان دستیابی به هدف، رعایت معیار پذیرش و بهبود نسبت به دوره قبل باید در تصمیم‌گیری حفظ شود. | K14: برای شاخص‌های محقق‌نشده، علت، اقدام، مسئول و معیار اثربخشی تعیین شود؛ در موارد متعارض هیچ مقدار مرجع انتخاب نشده است. | L14: DOC-SOURCE | M14: بررسی نشده | N14: نیازمند تعیین | R14: =IF(A14="","",IF(NOT(AND(COUNTIFS('03-ورودی‌های بازنگری'!$A$8:$A$1007,A14)=1,AND(COUNTIFS('17-جلسات و دوره‌ها'!$A$8:$A$1007,D14)=1,IFERROR(INDEX('17-جلسات و دوره‌ها'!$B$8:$B$1007,MATCH(D14,'17-جلسات و دوره‌ها'!$A$8:$A$1007,0)),"")=B14,IFERROR(INDEX('17-جلسات و دوره‌ها'!$C$8:$C$1007,MATCH(D14,'17-جلسات و دوره‌ها'!$A$8:$A$1007,0)),"")=C14))),"شناسه یا جلسه نامعتبر",IF(AND(M14="بررسی شد",J14<>"",O14<>"",P14<>"",Q14<>"",AND(COUNTIFS('14-مستندات و پیوست‌ها'!$A$8:$A$1007,L14)=1,IFERROR(INDEX('14-مستندات و پیوست‌ها'!$B$8:$B$1007,MATCH(L14,'14-مستندات و پیوست‌ها'!$A$8:$A$1007,0)),"")=B14,OR(IFERROR(INDEX('14-مستندات و پیوست‌ها'!$H$8:$H$1007,MATCH(L14,'14-مستندات و پیوست‌ها'!$A$8:$A$1007,0)),"")="دریافت شده",IFERROR(INDEX('14-مستندات و پیوست‌ها'!$H$8:$H$1007,MATCH(L14,'14-مستندات و پیوست‌ها'!$A$8:$A$1007,0)),"")="فرضی"))),"معتبر","بررسی یا شاهد ناقص"))) -> بررسی یا شاهد ناقص
A15: IN-R08 | B15: NIPCO | C15: P-BASE | D15: MR-NIPCO-BASE | E15: واقعی؛ نیازمند تأیید | F15: ممیزی‌های داخلی | G15: IMS | H15: ممیزی‌های داخلی | I15: HSE 3؛ LOG 5-7 و 5-7 (2) | J15: یافته‌ها شامل ضعف ردیابی، انبارش، صلاحیت، مستندات، کنترل محصول مشکوک، نگهداری، تکوین محصول و اجرای الزامات IMS است. ثبت تفصیلی یافته‌ها در کاربرگ «ممیزی و شواهد» آمده است. | K15: هر یافته به اقدام متناسب متصل شود. نیازسنجی آموزشی به‌تنهایی پاسخ کافی برای همه مسائل زیرساختی و سیستمی نیست. | L15: DOC-SOURCE | M15: بررسی نشده | N15: نیازمند تعیین | R15: =IF(A15="","",IF(NOT(AND(COUNTIFS('03-ورودی‌های بازنگری'!$A$8:$A$1007,A15)=1,AND(COUNTIFS('17-جلسات و دوره‌ها'!$A$8:$A$1007,D15)=1,IFERROR(INDEX('17-جلسات و دوره‌ها'!$B$8:$B$1007,MATCH(D15,'17-جلسات و دوره‌ها'!$A$8:$A$1007,0)),"")=B15,IFERROR(INDEX('17-جلسات و دوره‌ها'!$C$8:$C$1007,MATCH(D15,'17-جلسات و دوره‌ها'!$A$8:$A$1007,0)),"")=C15))),"شناسه یا جلسه نامعتبر",IF(AND(M15="بررسی شد",J15<>"",O15<>"",P15<>"",Q15<>"",AND(COUNTIFS('14-مستندات و پیوست‌ها'!$A$8:$A$1007,L15)=1,IFERROR(INDEX('14-مستندات و پیوست‌ها'!$B$8:$B$1007,MATCH(L15,'14-مستندات و پیوست‌ها'!$A$8:$A$1007,0)),"")=B15,OR(IFERROR(INDEX('14-مستندات و پیوست‌ها'!$H$8:$H$1007,MATCH(L15,'14-مستندات و پیوست‌ها'!$A$8:$A$1007,0)),"")="دریافت شده",IFERROR(INDEX('14-مستندات و پیوست‌ها'!$H$8:$H$1007,MATCH(L15,'14-مستندات و پیوست‌ها'!$A$8:$A$1007,0)),"")="فرضی"))),"معتبر","بررسی یا شاهد ناقص"))) -> بررسی یا شاهد ناقص
A16: IN-R09 | B16: NIPCO | C16: P-BASE | D16: MR-NIPCO-BASE | E16: واقعی؛ نیازمند تأیید | F16: ممیزی‌های خارجی و گواهینامه | G16: IMS | H16: ممیزی‌های خارجی و گواهینامه | I16: HSE 3!C27 و 15!C11؛ LOG 1!G4:G5 و 15!C9 | J16: گزارش‌ها به ممیزی مشتری، گرید B+، هدف گرید A و ممیزی مراقبتی IMS اشاره دارند. متن HSE هم‌زمان از نبود برنامه ممیزی و اجرای برنامه سه‌ساله سخن می‌گوید. | K16: شماره و تاریخ گزارش‌های خارجی، دامنه و وضعیت عدم‌انطباق‌ها و برنامه جاری ممیزی به سند متصل شود. | L16: DOC-SOURCE | M16: بررسی نشده | N16: نیازمند تعیین | R16: =IF(A16="","",IF(NOT(AND(COUNTIFS('03-ورودی‌های بازنگری'!$A$8:$A$1007,A16)=1,AND(COUNTIFS('17-جلسات و دوره‌ها'!$A$8:$A$1007,D16)=1,IFERROR(INDEX('17-جلسات و دوره‌ها'!$B$8:$B$1007,MATCH(D16,'17-جلسات و دوره‌ها'!$A$8:$A$1007,0)),"")=B16,IFERROR(INDEX('17-جلسات و دوره‌ها'!$C$8:$C$1007,MATCH(D16,'17-جلسات و دوره‌ها'!$A$8:$A$1007,0)),"")=C16))),"شناسه یا جلسه نامعتبر",IF(AND(M16="بررسی شد",J16<>"",O16<>"",P16<>"",Q16<>"",AND(COUNTIFS('14-مستندات و پیوست‌ها'!$A$8:$A$1007,L16)=1,IFERROR(INDEX('14-مستندات و پیوست‌ها'!$B$8:$B$1007,MATCH(L16,'14-مستندات و پیوست‌ها'!$A$8:$A$1007,0)),"")=B16,OR(IFERROR(INDEX('14-مستندات و پیوست‌ها'!$H$8:$H$1007,MATCH(L16,'14-مستندات و پیوست‌ها'!$A$8:$A$1007,0)),"")="دریافت شده",IFERROR(INDEX('14-مستندات و پیوست‌ها'!$H$8:$H$1007,MATCH(L16,'14-مستندات و پیوست‌ها'!$A$8:$A$1007,0)),"")="فرضی"))),"معتبر","بررسی یا شاهد ناقص"))) -> بررسی یا شاهد ناقص
A17: IN-R10 | B17: NIPCO | C17: P-BASE | D17: MR-NIPCO-BASE | E17: واقعی؛ نیازمند تأیید | F17: اقدامات اصلاحی و اثربخشی | G17: IMS | H17: اقدامات اصلاحی و اثربخشی | I17: HSE 14!C11؛ LOG 14!C11 و 2-4!F14 | J17: در هر دو گزارش تصریح شده که بستن اقدام در اتوماسیون با اثربخشی آن یکسان تلقی می‌شود. این ضعف اعتبار شاخص اثربخشی اقدامات اصلاحی را تحت تأثیر قرار می‌دهد. | K17: گردش کار به مراحل تحلیل علت، اجرای اقدام، تصدیق اجرا و ارزیابی اثربخشی تفکیک شود. نتیجه و شواهد هر مرحله ثبت گردد. | L17: DOC-SOURCE | M17: بررسی نشده | N17: نیازمند تعیین | R17: =IF(A17="","",IF(NOT(AND(COUNTIFS('03-ورودی‌های بازنگری'!$A$8:$A$1007,A17)=1,AND(COUNTIFS('17-جلسات و دوره‌ها'!$A$8:$A$1007,D17)=1,IFERROR(INDEX('17-جلسات و دوره‌ها'!$B$8:$B$1007,MATCH(D17,'17-جلسات و دوره‌ها'!$A$8:$A$1007,0)),"")=B17,IFERROR(INDEX('17-جلسات و دوره‌ها'!$C$8:$C$1007,MATCH(D17,'17-جلسات و دوره‌ها'!$A$8:$A$1007,0)),"")=C17))),"شناسه یا جلسه نامعتبر",IF(AND(M17="بررسی شد",J17<>"",O17<>"",P17<>"",Q17<>"",AND(COUNTIFS('14-مستندات و پیوست‌ها'!$A$8:$A$1007,L17)=1,IFERROR(INDEX('14-مستندات و پیوست‌ها'!$B$8:$B$1007,MATCH(L17,'14-مستندات و پیوست‌ها'!$A$8:$A$1007,0)),"")=B17,OR(IFERROR(INDEX('14-مستندات و پیوست‌ها'!$H$8:$H$1007,MATCH(L17,'14-مستندات و پیوست‌ها'!$A$8:$A$1007,0)),"")="دریافت شده",IFERROR(INDEX('14-مستندات و پیوست‌ها'!$H$8:$H$1007,MATCH(L17,'14-مستندات و پیوست‌ها'!$A$8:$A$1007,0)),"")="فرضی"))),"معتبر","بررسی یا شاهد ناقص"))) -> بررسی یا شاهد ناقص
A18: IN-R11 | B18: NIPCO | C18: P-BASE | D18: MR-NIPCO-BASE | E18: واقعی؛ نیازمند تأیید | F18: انطباق محصول، کلیم و ضمانت | G18: IMS | H18: انطباق محصول، کلیم و ضمانت | I18: LOG 14!C5:O17؛ 13!C5؛ 2-4!B28:F33 | J18: PPM مشتریان، شماره‌های فنی دارای کلیم و تعداد تکرار کلیم در گزارش درج شده است. نبود شکایت عرصه مصرف و برنامه بازدید از انبار داغی‌ها نیز گزارش شده است. | K18: شکایت تولیدی مشتری، برگشتی ضمانت و خرابی عرصه مصرف تفکیک شوند. پارتو و بازرسی ابعادی با شناسه شاهد پیوند یابند. | L18: DOC-SOURCE | M18: بررسی نشده | N18: نیازمند تعیین | R18: =IF(A18="","",IF(NOT(AND(COUNTIFS('03-ورودی‌های بازنگری'!$A$8:$A$1007,A18)=1,AND(COUNTIFS('17-جلسات و دوره‌ها'!$A$8:$A$1007,D18)=1,IFERROR(INDEX('17-جلسات و دوره‌ها'!$B$8:$B$1007,MATCH(D18,'17-جلسات و دوره‌ها'!$A$8:$A$1007,0)),"")=B18,IFERROR(INDEX('17-جلسات و دوره‌ها'!$C$8:$C$1007,MATCH(D18,'17-جلسات و دوره‌ها'!$A$8:$A$1007,0)),"")=C18))),"شناسه یا جلسه نامعتبر",IF(AND(M18="بررسی شد",J18<>"",O18<>"",P18<>"",Q18<>"",AND(COUNTIFS('14-مستندات و پیوست‌ها'!$A$8:$A$1007,L18)=1,IFERROR(INDEX('14-مستندات و پیوست‌ها'!$B$8:$B$1007,MATCH(L18,'14-مستندات و پیوست‌ها'!$A$8:$A$1007,0)),"")=B18,OR(IFERROR(INDEX('14-مستندات و پیوست‌ها'!$H$8:$H$1007,MATCH(L18,'14-مستندات و پیوست‌ها'!$A$8:$A$1007,0)),"")="دریافت شده",IFERROR(INDEX('14-مستندات و پیوست‌ها'!$H$8:$H$1007,MATCH(L18,'14-مستندات و پیوست‌ها'!$A$8:$A$1007,0)),"")="فرضی"))),"معتبر","بررسی یا شاهد ناقص"))) -> بررسی یا شاهد ناقص
A19: IN-R12 | B19: NIPCO | C19: P-BASE | D19: MR-NIPCO-BASE | E19: واقعی؛ نیازمند تأیید | F19: اندازه‌گیری و قابلیت فرآیند | G19: IMS | H19: اندازه‌گیری و قابلیت فرآیند | I19: LOG 8-9!C5:F15 | J19: در منبع لجستیک R&R کولیس یک‌متری ۸٫۲۱، Cmk ماشین پانچ ۱٫۸۹ و برای مشخصه معرفی‌شده Cp=2.45 و Cpk=1.68 ثبت شده است. اجرای MSA وصفی نیز اعلام شده است. | K19: واحد R&R، طرح نمونه‌برداری، پایداری فرآیند، حدود پذیرش و شناسه مطالعه مشخص شود؛ اعداد به‌تنهایی برای نتیجه انطباق کافی نیستند. | L19: DOC-SOURCE | M19: بررسی نشده | N19: نیازمند تعیین | R19: =IF(A19="","",IF(NOT(AND(COUNTIFS('03-ورودی‌های بازنگری'!$A$8:$A$1007,A19)=1,AND(COUNTIFS('17-جلسات و دوره‌ها'!$A$8:$A$1007,D19)=1,IFERROR(INDEX('17-جلسات و دوره‌ها'!$B$8:$B$1007,MATCH(D19,'17-جلسات و دوره‌ها'!$A$8:$A$1007,0)),"")=B19,IFERROR(INDEX('17-جلسات و دوره‌ها'!$C$8:$C$1007,MATCH(D19,'17-جلسات و دوره‌ها'!$A$8:$A$1007,0)),"")=C19))),"شناسه یا جلسه نامعتبر",IF(AND(M19="بررسی شد",J19<>"",O19<>"",P19<>"",Q19<>"",AND(COUNTIFS('14-مستندات و پیوست‌ها'!$A$8:$A$1007,L19)=1,IFERROR(INDEX('14-مستندات و پیوست‌ها'!$B$8:$B$1007,MATCH(L19,'14-مستندات و پیوست‌ها'!$A$8:$A$1007,0)),"")=B19,OR(IFERROR(INDEX('14-مستندات و پیوست‌ها'!$H$8:$H$1007,MATCH(L19,'14-مستندات و پیوست‌ها'!$A$8:$A$1007,0)),"")="دریافت شده",IFERROR(INDEX('14-مستندات و پیوست‌ها'!$H$8:$H$1007,MATCH(L19,'14-مستندات و پیوست‌ها'!$A$8:$A$1007,0)),"")="فرضی"))),"معتبر","بررسی یا شاهد ناقص"))) -> بررسی یا شاهد ناقص
... A36: IN-R29 | B36: NIPCO | C36: P-BASE | D36: MR-NIPCO-BASE | E36: واقعی؛ نیازمند تأیید | F36: نتیجه‌گیری بازنگری | G36: HSE | H36: نتیجه‌گیری بازنگری | I36: جمع‌بندی بررسی اسناد | J36: دو سند، ورودی‌های گسترده و نیازهای واقعی بهبود را پوشش می‌دهند؛ اما ناسازگاری داده‌ها و نبود شواهد قابل بازیابی در بسته فعلی، نتیجه‌گیری قطعی درباره کفایت و اثربخشی کل سیستم را محدود می‌کند. این جمله ارزیابی مستندات است، نه مصوبه مدیریت. | K36: مدیریت پس از تطبیق شاخص‌ها و بررسی شواهد، نتیجه مستقل درباره تناسب، کفایت، اثربخشی و هم‌راستایی راهبردی هر حوزه را ثبت و تصویب کند. | L36: DOC-SOURCE | M36: بررسی نشده | N36: نیازمند تعیین | R36: =IF(A36="","",IF(NOT(AND(COUNTIFS('03-ورودی‌های بازنگری'!$A$8:$A$1007,A36)=1,AND(COUNTIFS('17-جلسات و دوره‌ها'!$A$8:$A$1007,D36)=1,IFERROR(INDEX('17-جلسات و دوره‌ها'!$B$8:$B$1007,MATCH(D36,'17-جلسات و دوره‌ها'!$A$8:$A$1007,0)),"")=B36,IFERROR(INDEX('17-جلسات و دوره‌ها'!$C$8:$C$1007,MATCH(D36,'17-جلسات و دوره‌ها'!$A$8:$A$1007,0)),"")=C36))),"شناسه یا جلسه نامعتبر",IF(AND(M36="بررسی شد",J36<>"",O36<>"",P36<>"",Q36<>"",AND(COUNTIFS('14-مستندات و پیوست‌ها'!$A$8:$A$1007,L36)=1,IFERROR(INDEX('14-مستندات و پیوست‌ها'!$B$8:$B$1007,MATCH(L36,'14-مستندات و پیوست‌ها'!$A$8:$A$1007,0)),"")=B36,OR(IFERROR(INDEX('14-مستندات و پیوست‌ها'!$H$8:$H$1007,MATCH(L36,'14-مستندات و پیوست‌ها'!$A$8:$A$1007,0)),"")="دریافت شده",IFERROR(INDEX('14-مستندات و پیوست‌ها'!$H$8:$H$1007,MATCH(L36,'14-مستندات و پیوست‌ها'!$A$8:$A$1007,0)),"")="فرضی"))),"معتبر","بررسی یا شاهد ناقص"))) -> بررسی یا شاهد ناقص
A37: IN-S1 | B37: DEMO | C37: P-DEMO | D37: MR-DEMO-01 | E37: فرضی؛ صرفاً آموزش | F37: کیفیت مشتری | G37: IATF | H37: PPM بالاتر از هدف | I37: DOC-DEMO | J37: داده فرضی برای آزمون مسیر تصمیم‌گیری؛ گزارش واقعی شرکت نیست. | K37: بررسی و تعیین تکلیف در سناریوی آموزشی | L37: DOC-DEMO | M37: بررسی شد | N37: بالا | O37: تحلیل سناریوی فرضی بررسی شد. | P37: ارزیاب فرضی | Q37: DEMO-APP | R37: =IF(A37="","",IF(NOT(AND(COUNTIFS('03-ورودی‌های بازنگری'!$A$8:$A$1007,A37)=1,AND(COUNTIFS('17-جلسات و دوره‌ها'!$A$8:$A$1007,D37)=1,IFERROR(INDEX('17-جلسات و دوره‌ها'!$B$8:$B$1007,MATCH(D37,'17-جلسات و دوره‌ها'!$A$8:$A$1007,0)),"")=B37,IFERROR(INDEX('17-جلسات و دوره‌ها'!$C$8:$C$1007,MATCH(D37,'17-جلسات و دوره‌ها'!$A$8:$A$1007,0)),"")=C37))),"شناسه یا جلسه نامعتبر",IF(AND(M37="بررسی شد",J37<>"",O37<>"",P37<>"",Q37<>"",AND(COUNTIFS('14-مستندات و پیوست‌ها'!$A$8:$A$1007,L37)=1,IFERROR(INDEX('14-مستندات و پیوست‌ها'!$B$8:$B$1007,MATCH(L37,'14-مستندات و پیوست‌ها'!$A$8:$A$1007,0)),"")=B37,OR(IFERROR(INDEX('14-مستندات و پیوست‌ها'!$H$8:$H$1007,MATCH(L37,'14-مستندات و پیوست‌ها'!$A$8:$A$1007,0)),"")="دریافت شده",IFERROR(INDEX('14-مستندات و پیوست‌ها'!$H$8:$H$1007,MATCH(L37,'14-مستندات و پیوست‌ها'!$A$8:$A$1007,0)),"")="فرضی"))),"معتبر","بررسی یا شاهد ناقص"))) -> معتبر
A38: IN-S2 | B38: DEMO | C38: P-DEMO | D38: MR-DEMO-01 | E38: فرضی؛ صرفاً آموزش | F38: ظرفیت | G38: QMS | H38: خرید تجهیز ظرفیت | I38: DOC-DEMO | J38: داده فرضی برای آزمون مسیر تصمیم‌گیری؛ گزارش واقعی شرکت نیست. | K38: بررسی و تعیین تکلیف در سناریوی آموزشی | L38: DOC-DEMO | M38: بررسی شد | N38: بالا | O38: تحلیل سناریوی فرضی بررسی شد. | P38: ارزیاب فرضی | Q38: DEMO-APP | R38: =IF(A38="","",IF(NOT(AND(COUNTIFS('03-ورودی‌های بازنگری'!$A$8:$A$1007,A38)=1,AND(COUNTIFS('17-جلسات و دوره‌ها'!$A$8:$A$1007,D38)=1,IFERROR(INDEX('17-جلسات و دوره‌ها'!$B$8:$B$1007,MATCH(D38,'17-جلسات و دوره‌ها'!$A$8:$A$1007,0)),"")=B38,IFERROR(INDEX('17-جلسات و دوره‌ها'!$C$8:$C$1007,MATCH(D38,'17-جلسات و دوره‌ها'!$A$8:$A$1007,0)),"")=C38))),"شناسه یا جلسه نامعتبر",IF(AND(M38="بررسی شد",J38<>"",O38<>"",P38<>"",Q38<>"",AND(COUNTIFS('14-مستندات و پیوست‌ها'!$A$8:$A$1007,L38)=1,IFERROR(INDEX('14-مستندات و پیوست‌ها'!$B$8:$B$1007,MATCH(L38,'14-مستندات و پیوست‌ها'!$A$8:$A$1007,0)),"")=B38,OR(IFERROR(INDEX('14-مستندات و پیوست‌ها'!$H$8:$H$1007,MATCH(L38,'14-مستندات و پیوست‌ها'!$A$8:$A$1007,0)),"")="دریافت شده",IFERROR(INDEX('14-مستندات و پیوست‌ها'!$H$8:$H$1007,MATCH(L38,'14-مستندات و پیوست‌ها'!$A$8:$A$1007,0)),"")="فرضی"))),"معتبر","بررسی یا شاهد ناقص"))) -> معتبر
A39: IN-S3 | B39: DEMO | C39: P-DEMO | D39: MR-DEMO-01 | E39: فرضی؛ صرفاً آموزش | F39: محیط‌زیست | G39: EMS | H39: مصرف انرژی بالاتر از هدف | I39: DOC-DEMO | J39: داده فرضی برای آزمون مسیر تصمیم‌گیری؛ گزارش واقعی شرکت نیست. | K39: بررسی و تعیین تکلیف در سناریوی آموزشی | L39: DOC-DEMO | M39: بررسی شد | N39: بالا | O39: تحلیل سناریوی فرضی بررسی شد. | P39: ارزیاب فرضی | Q39: DEMO-APP | R39: =IF(A39="","",IF(NOT(AND(COUNTIFS('03-ورودی‌های بازنگری'!$A$8:$A$1007,A39)=1,AND(COUNTIFS('17-جلسات و دوره‌ها'!$A$8:$A$1007,D39)=1,IFERROR(INDEX('17-جلسات و دوره‌ها'!$B$8:$B$1007,MATCH(D39,'17-جلسات و دوره‌ها'!$A$8:$A$1007,0)),"")=B39,IFERROR(INDEX('17-جلسات و دوره‌ها'!$C$8:$C$1007,MATCH(D39,'17-جلسات و دوره‌ها'!$A$8:$A$1007,0)),"")=C39))),"شناسه یا جلسه نامعتبر",IF(AND(M39="بررسی شد",J39<>"",O39<>"",P39<>"",Q39<>"",AND(COUNTIFS('14-مستندات و پیوست‌ها'!$A$8:$A$1007,L39)=1,IFERROR(INDEX('14-مستندات و پیوست‌ها'!$B$8:$B$1007,MATCH(L39,'14-مستندات و پیوست‌ها'!$A$8:$A$1007,0)),"")=B39,OR(IFERROR(INDEX('14-مستندات و پیوست‌ها'!$H$8:$H$1007,MATCH(L39,'14-مستندات و پیوست‌ها'!$A$8:$A$1007,0)),"")="دریافت شده",IFERROR(INDEX('14-مستندات و پیوست‌ها'!$H$8:$H$1007,MATCH(L39,'14-مستندات و پیوست‌ها'!$A$8:$A$1007,0)),"")="فرضی"))),"معتبر","بررسی یا شاهد ناقص"))) -> معتبر
A40: IN-S4 | B40: DEMO | C40: P-DEMO | D40: MR-DEMO-01 | E40: فرضی؛ صرفاً آموزش | F40: ایمنی | G40: OHS | H40: خطر مهم ایمنی | I40: DOC-DEMO | J40: داده فرضی برای آزمون مسیر تصمیم‌گیری؛ گزارش واقعی شرکت نیست. | K40: بررسی و تعیین تکلیف در سناریوی آموزشی | L40: DOC-DEMO | M40: بررسی شد | N40: بالا | O40: تحلیل سناریوی فرضی بررسی شد. | P40: ارزیاب فرضی | Q40: DEMO-APP | R40: =IF(A40="","",IF(NOT(AND(COUNTIFS('03-ورودی‌های بازنگری'!$A$8:$A$1007,A40)=1,AND(COUNTIFS('17-جلسات و دوره‌ها'!$A$8:$A$1007,D40)=1,IFERROR(INDEX('17-جلسات و دوره‌ها'!$B$8:$B$1007,MATCH(D40,'17-جلسات و دوره‌ها'!$A$8:$A$1007,0)),"")=B40,IFERROR(INDEX('17-جلسات و دوره‌ها'!$C$8:$C$1007,MATCH(D40,'17-جلسات و دوره‌ها'!$A$8:$A$1007,0)),"")=C40))),"شناسه یا جلسه نامعتبر",IF(AND(M40="بررسی شد",J40<>"",O40<>"",P40<>"",Q40<>"",AND(COUNTIFS('14-مستندات و پیوست‌ها'!$A$8:$A$1007,L40)=1,IFERROR(INDEX('14-مستندات و پیوست‌ها'!$B$8:$B$1007,MATCH(L40,'14-مستندات و پیوست‌ها'!$A$8:$A$1007,0)),"")=B40,OR(IFERROR(INDEX('14-مستندات و پیوست‌ها'!$H$8:$H$1007,MATCH(L40,'14-مستندات و پیوست‌ها'!$A$8:$A$1007,0)),"")="دریافت شده",IFERROR(INDEX('14-مستندات و پیوست‌ها'!$H$8:$H$1007,MATCH(L40,'14-مستندات و پیوست‌ها'!$A$8:$A$1007,0)),"")="فرضی"))),"معتبر","بررسی یا شاهد ناقص"))) -> معتبر
A41: IN-S5 | B41: DEMO | C41: P-DEMO | D41: MR-DEMO-01 | E41: فرضی؛ صرفاً آموزش | F41: کیفیت | G41: QMS | H41: هدف محقق‌شده بدون نیاز تغییر | I41: DOC-DEMO | J41: داده فرضی برای آزمون مسیر تصمیم‌گیری؛ گزارش واقعی شرکت نیست. | K41: بررسی و تعیین تکلیف در سناریوی آموزشی | L41: DOC-DEMO | M41: بررسی شد | N41: بالا | O41: تحلیل سناریوی فرضی بررسی شد. | P41: ارزیاب فرضی | Q41: DEMO-APP | R41: =IF(A41="","",IF(NOT(AND(COUNTIFS('03-ورودی‌های بازنگری'!$A$8:$A$1007,A41)=1,AND(COUNTIFS('17-جلسات و دوره‌ها'!$A$8:$A$1007,D41)=1,IFERROR(INDEX('17-جلسات و دوره‌ها'!$B$8:$B$1007,MATCH(D41,'17-جلسات و دوره‌ها'!$A$8:$A$1007,0)),"")=B41,IFERROR(INDEX('17-جلسات و دوره‌ها'!$C$8:$C$1007,MATCH(D41,'17-جلسات و دوره‌ها'!$A$8:$A$1007,0)),"")=C41))),"شناسه یا جلسه نامعتبر",IF(AND(M41="بررسی شد",J41<>"",O41<>"",P41<>"",Q41<>"",AND(COUNTIFS('14-مستندات و پیوست‌ها'!$A$8:$A$1007,L41)=1,IFERROR(INDEX('14-مستندات و پیوست‌ها'!$B$8:$B$1007,MATCH(L41,'14-مستندات و پیوست‌ها'!$A$8:$A$1007,0)),"")=B41,OR(IFERROR(INDEX('14-مستندات و پیوست‌ها'!$H$8:$H$1007,MATCH(L41,'14-مستندات و پیوست‌ها'!$A$8:$A$1007,0)),"")="دریافت شده",IFERROR(INDEX('14-مستندات و پیوست‌ها'!$H$8:$H$1007,MATCH(L41,'14-مستندات و پیوست‌ها'!$A$8:$A$1007,0)),"")="فرضی"))),"معتبر","بررسی یا شاهد ناقص"))) -> معتبر
A42: IN-S6 | B42: DEMO | C42: P-DEMO | D42: MR-DEMO-01 | E42: فرضی؛ صرفاً آموزش | F42: تعمیرات | G42: QMS | H42: اقدام اجراشده بدون اثربخشی | I42: DOC-DEMO | J42: داده فرضی برای آزمون مسیر تصمیم‌گیری؛ گزارش واقعی شرکت نیست. | K42: بررسی و تعیین تکلیف در سناریوی آموزشی | L42: DOC-DEMO | M42: بررسی شد | N42: بالا | O42: تحلیل سناریوی فرضی بررسی شد. | P42: ارزیاب فرضی | Q42: DEMO-APP | R42: =IF(A42="","",IF(NOT(AND(COUNTIFS('03-ورودی‌های بازنگری'!$A$8:$A$1007,A42)=1,AND(COUNTIFS('17-جلسات و دوره‌ها'!$A$8:$A$1007,D42)=1,IFERROR(INDEX('17-جلسات و دوره‌ها'!$B$8:$B$1007,MATCH(D42,'17-جلسات و دوره‌ها'!$A$8:$A$1007,0)),"")=B42,IFERROR(INDEX('17-جلسات و دوره‌ها'!$C$8:$C$1007,MATCH(D42,'17-جلسات و دوره‌ها'!$A$8:$A$1007,0)),"")=C42))),"شناسه یا جلسه نامعتبر",IF(AND(M42="بررسی شد",J42<>"",O42<>"",P42<>"",Q42<>"",AND(COUNTIFS('14-مستندات و پیوست‌ها'!$A$8:$A$1007,L42)=1,IFERROR(INDEX('14-مستندات و پیوست‌ها'!$B$8:$B$1007,MATCH(L42,'14-مستندات و پیوست‌ها'!$A$8:$A$1007,0)),"")=B42,OR(IFERROR(INDEX('14-مستندات و پیوست‌ها'!$H$8:$H$1007,MATCH(L42,'14-مستندات و پیوست‌ها'!$A$8:$A$1007,0)),"")="دریافت شده",IFERROR(INDEX('14-مستندات و پیوست‌ها'!$H$8:$H$1007,MATCH(L42,'14-مستندات و پیوست‌ها'!$A$8:$A$1007,0)),"")="فرضی"))),"معتبر","بررسی یا شاهد ناقص"))) -> معتبر
A43: IN-S7 | B43: DEMO | C43: P-DEMO | D43: MR-DEMO-01 | E43: فرضی؛ صرفاً آموزش | F43: منابع | G43: QMS | H43: رد درخواست منبع | I43: DOC-DEMO | J43: داده فرضی برای آزمون مسیر تصمیم‌گیری؛ گزارش واقعی شرکت نیست. | K43: بررسی و تعیین تکلیف در سناریوی آموزشی | L43: DOC-DEMO | M43: بررسی شد | N43: بالا | O43: تحلیل سناریوی فرضی بررسی شد. | P43: ارزیاب فرضی | Q43: DEMO-APP | R43: =IF(A43="","",IF(NOT(AND(COUNTIFS('03-ورودی‌های بازنگری'!$A$8:$A$1007,A43)=1,AND(COUNTIFS('17-جلسات و دوره‌ها'!$A$8:$A$1007,D43)=1,IFERROR(INDEX('17-جلسات و دوره‌ها'!$B$8:$B$1007,MATCH(D43,'17-جلسات و دوره‌ها'!$A$8:$A$1007,0)),"")=B43,IFERROR(INDEX('17-جلسات و دوره‌ها'!$C$8:$C$1007,MATCH(D43,'17-جلسات و دوره‌ها'!$A$8:$A$1007,0)),"")=C43))),"شناسه یا جلسه نامعتبر",IF(AND(M43="بررسی شد",J43<>"",O43<>"",P43<>"",Q43<>"",AND(COUNTIFS('14-مستندات و پیوست‌ها'!$A$8:$A$1007,L43)=1,IFERROR(INDEX('14-مستندات و پیوست‌ها'!$B$8:$B$1007,MATCH(L43,'14-مستندات و پیوست‌ها'!$A$8:$A$1007,0)),"")=B43,OR(IFERROR(INDEX('14-مستندات و پیوست‌ها'!$H$8:$H$1007,MATCH(L43,'14-مستندات و پیوست‌ها'!$A$8:$A$1007,0)),"")="دریافت شده",IFERROR(INDEX('14-مستندات و پیوست‌ها'!$H$8:$H$1007,MATCH(L43,'14-مستندات و پیوست‌ها'!$A$8:$A$1007,0)),"")="فرضی"))),"معتبر","بررسی یا شاهد ناقص"))) -> معتبر
R44: =IF(A44="","",IF(NOT(AND(COUNTIFS('03-ورودی‌های بازنگری'!$A$8:$A$1007,A44)=1,AND(COUNTIFS('17-جلسات و دوره‌ها'!$A$8:$A$1007,D44)=1,IFERROR(INDEX('17-جلسات و دوره‌ها'!$B$8:$B$1007,MATCH(D44,'17-جلسات و دوره‌ها'!$A$8:$A$1007,0)),"")=B44,IFERROR(INDEX('17-جلسات و دوره‌ها'!$C$8:$C$1007,MATCH(D44,'17-جلسات و دوره‌ها'!$A$8:$A$1007,0)),"")=C44))),"شناسه یا جلسه نامعتبر",IF(AND(M44="بررسی شد",J44<>"",O44<>"",P44<>"",Q44<>"",AND(COUNTIFS('14-مستندات و پیوست‌ها'!$A$8:$A$1007,L44)=1,IFERROR(INDEX('14-مستندات و پیوست‌ها'!$B$8:$B$1007,MATCH(L44,'14-مستندات و پیوست‌ها'!$A$8:$A$1007,0)),"")=B44,OR(IFERROR(INDEX('14-مستندات و پیوست‌ها'!$H$8:$H$1007,MATCH(L44,'14-مستندات و پیوست‌ها'!$A$8:$A$1007,0)),"")="دریافت شده",IFERROR(INDEX('14-مستندات و پیوست‌ها'!$H$8:$H$1007,MATCH(L44,'14-مستندات و پیوست‌ها'!$A$8:$A$1007,0)),"")="فرضی"))),"معتبر","بررسی یا شاهد ناقص")))
R45: =IF(A45="","",IF(NOT(AND(COUNTIFS('03-ورودی‌های بازنگری'!$A$8:$A$1007,A45)=1,AND(COUNTIFS('17-جلسات و دوره‌ها'!$A$8:$A$1007,D45)=1,IFERROR(INDEX('17-جلسات و دوره‌ها'!$B$8:$B$1007,MATCH(D45,'17-جلسات و دوره‌ها'!$A$8:$A$1007,0)),"")=B45,IFERROR(INDEX('17-جلسات و دوره‌ها'!$C$8:$C$1007,MATCH(D45,'17-جلسات و دوره‌ها'!$A$8:$A$1007,0)),"")=C45))),"شناسه یا جلسه نامعتبر",IF(AND(M45="بررسی شد",J45<>"",O45<>"",P45<>"",Q45<>"",AND(COUNTIFS('14-مستندات و پیوست‌ها'!$A$8:$A$1007,L45)=1,IFERROR(INDEX('14-مستندات و پیوست‌ها'!$B$8:$B$1007,MATCH(L45,'14-مستندات و پیوست‌ها'!$A$8:$A$1007,0)),"")=B45,OR(IFERROR(INDEX('14-مستندات و پیوست‌ها'!$H$8:$H$1007,MATCH(L45,'14-مستندات و پیوست‌ها'!$A$8:$A$1007,0)),"")="دریافت شده",IFERROR(INDEX('14-مستندات و پیوست‌ها'!$H$8:$H$1007,MATCH(L45,'14-مستندات و پیوست‌ها'!$A$8:$A$1007,0)),"")="فرضی"))),"معتبر","بررسی یا شاهد ناقص")))
R46: =IF(A46="","",IF(NOT(AND(COUNTIFS('03-ورودی‌های بازنگری'!$A$8:$A$1007,A46)=1,AND(COUNTIFS('17-جلسات و دوره‌ها'!$A$8:$A$1007,D46)=1,IFERROR(INDEX('17-جلسات و دوره‌ها'!$B$8:$B$1007,MATCH(D46,'17-جلسات و دوره‌ها'!$A$8:$A$1007,0)),"")=B46,IFERROR(INDEX('17-جلسات و دوره‌ها'!$C$8:$C$1007,MATCH(D46,'17-جلسات و دوره‌ها'!$A$8:$A$1007,0)),"")=C46))),"شناسه یا جلسه نامعتبر",IF(AND(M46="بررسی شد",J46<>"",O46<>"",P46<>"",Q46<>"",AND(COUNTIFS('14-مستندات و پیوست‌ها'!$A$8:$A$1007,L46)=1,IFERROR(INDEX('14-مستندات و پیوست‌ها'!$B$8:$B$1007,MATCH(L46,'14-مستندات و پیوست‌ها'!$A$8:$A$1007,0)),"")=B46,OR(IFERROR(INDEX('14-مستندات و پیوست‌ها'!$H$8:$H$1007,MATCH(L46,'14-مستندات و پیوست‌ها'!$A$8:$A$1007,0)),"")="دریافت شده",IFERROR(INDEX('14-مستندات و پیوست‌ها'!$H$8:$H$1007,MATCH(L46,'14-مستندات و پیوست‌ها'!$A$8:$A$1007,0)),"")="فرضی"))),"معتبر","بررسی یا شاهد ناقص")))
R47: =IF(A47="","",IF(NOT(AND(COUNTIFS('03-ورودی‌های بازنگری'!$A$8:$A$1007,A47)=1,AND(COUNTIFS('17-جلسات و دوره‌ها'!$A$8:$A$1007,D47)=1,IFERROR(INDEX('17-جلسات و دوره‌ها'!$B$8:$B$1007,MATCH(D47,'17-جلسات و دوره‌ها'!$A$8:$A$1007,0)),"")=B47,IFERROR(INDEX('17-جلسات و دوره‌ها'!$C$8:$C$1007,MATCH(D47,'17-جلسات و دوره‌ها'!$A$8:$A$1007,0)),"")=C47))),"شناسه یا جلسه نامعتبر",IF(AND(M47="بررسی شد",J47<>"",O47<>"",P47<>"",Q47<>"",AND(COUNTIFS('14-مستندات و پیوست‌ها'!$A$8:$A$1007,L47)=1,IFERROR(INDEX('14-مستندات و پیوست‌ها'!$B$8:$B$1007,MATCH(L47,'14-مستندات و پیوست‌ها'!$A$8:$A$1007,0)),"")=B47,OR(IFERROR(INDEX('14-مستندات و پیوست‌ها'!$H$8:$H$1007,MATCH(L47,'14-مستندات و پیوست‌ها'!$A$8:$A$1007,0)),"")="دریافت شده",IFERROR(INDEX('14-مستندات و پیوست‌ها'!$H$8:$H$1007,MATCH(L47,'14-مستندات و پیوست‌ها'!$A$8:$A$1007,0)),"")="فرضی"))),"معتبر","بررسی یا شاهد ناقص")))
R48: =IF(A48="","",IF(NOT(AND(COUNTIFS('03-ورودی‌های بازنگری'!$A$8:$A$1007,A48)=1,AND(COUNTIFS('17-جلسات و دوره‌ها'!$A$8:$A$1007,D48)=1,IFERROR(INDEX('17-جلسات و دوره‌ها'!$B$8:$B$1007,MATCH(D48,'17-جلسات و دوره‌ها'!$A$8:$A$1007,0)),"")=B48,IFERROR(INDEX('17-جلسات و دوره‌ها'!$C$8:$C$1007,MATCH(D48,'17-جلسات و دوره‌ها'!$A$8:$A$1007,0)),"")=C48))),"شناسه یا جلسه نامعتبر",IF(AND(M48="بررسی شد",J48<>"",O48<>"",P48<>"",Q48<>"",AND(COUNTIFS('14-مستندات و پیوست‌ها'!$A$8:$A$1007,L48)=1,IFERROR(INDEX('14-مستندات و پیوست‌ها'!$B$8:$B$1007,MATCH(L48,'14-مستندات و پیوست‌ها'!$A$8:$A$1007,0)),"")=B48,OR(IFERROR(INDEX('14-مستندات و پیوست‌ها'!$H$8:$H$1007,MATCH(L48,'14-مستندات و پیوست‌ها'!$A$8:$A$1007,0)),"")="دریافت شده",IFERROR(INDEX('14-مستندات و پیوست‌ها'!$H$8:$H$1007,MATCH(L48,'14-مستندات و پیوست‌ها'!$A$8:$A$1007,0)),"")="فرضی"))),"معتبر","بررسی یا شاهد ناقص")))
R49: =IF(A49="","",IF(NOT(AND(COUNTIFS('03-ورودی‌های بازنگری'!$A$8:$A$1007,A49)=1,AND(COUNTIFS('17-جلسات و دوره‌ها'!$A$8:$A$1007,D49)=1,IFERROR(INDEX('17-جلسات و دوره‌ها'!$B$8:$B$1007,MATCH(D49,'17-جلسات و دوره‌ها'!$A$8:$A$1007,0)),"")=B49,IFERROR(INDEX('17-جلسات و دوره‌ها'!$C$8:$C$1007,MATCH(D49,'17-جلسات و دوره‌ها'!$A$8:$A$1007,0)),"")=C49))),"شناسه یا جلسه نامعتبر",IF(AND(M49="بررسی شد",J49<>"",O49<>"",P49<>"",Q49<>"",AND(COUNTIFS('14-مستندات و پیوست‌ها'!$A$8:$A$1007,L49)=1,IFERROR(INDEX('14-مستندات و پیوست‌ها'!$B$8:$B$1007,MATCH(L49,'14-مستندات و پیوست‌ها'!$A$8:$A$1007,0)),"")=B49,OR(IFERROR(INDEX('14-مستندات و پیوست‌ها'!$H$8:$H$1007,MATCH(L49,'14-مستندات و پیوست‌ها'!$A$8:$A$1007,0)),"")="دریافت شده",IFERROR(INDEX('14-مستندات و پیوست‌ها'!$H$8:$H$1007,MATCH(L49,'14-مستندات و پیوست‌ها'!$A$8:$A$1007,0)),"")="فرضی"))),"معتبر","بررسی یا شاهد ناقص")))
R50: =IF(A50="","",IF(NOT(AND(COUNTIFS('03-ورودی‌های بازنگری'!$A$8:$A$1007,A50)=1,AND(COUNTIFS('17-جلسات و دوره‌ها'!$A$8:$A$1007,D50)=1,IFERROR(INDEX('17-جلسات و دوره‌ها'!$B$8:$B$1007,MATCH(D50,'17-جلسات و دوره‌ها'!$A$8:$A$1007,0)),"")=B50,IFERROR(INDEX('17-جلسات و دوره‌ها'!$C$8:$C$1007,MATCH(D50,'17-جلسات و دوره‌ها'!$A$8:$A$1007,0)),"")=C50))),"شناسه یا جلسه نامعتبر",IF(AND(M50="بررسی شد",J50<>"",O50<>"",P50<>"",Q50<>"",AND(COUNTIFS('14-مستندات و پیوست‌ها'!$A$8:$A$1007,L50)=1,IFERROR(INDEX('14-مستندات و پیوست‌ها'!$B$8:$B$1007,MATCH(L50,'14-مستندات و پیوست‌ها'!$A$8:$A$1007,0)),"")=B50,OR(IFERROR(INDEX('14-مستندات و پیوست‌ها'!$H$8:$H$1007,MATCH(L50,'14-مستندات و پیوست‌ها'!$A$8:$A$1007,0)),"")="دریافت شده",IFERROR(INDEX('14-مستندات و پیوست‌ها'!$H$8:$H$1007,MATCH(L50,'14-مستندات و پیوست‌ها'!$A$8:$A$1007,0)),"")="فرضی"))),"معتبر","بررسی یا شاهد ناقص")))
R51: =IF(A51="","",IF(NOT(AND(COUNTIFS('03-ورودی‌های بازنگری'!$A$8:$A$1007,A51)=1,AND(COUNTIFS('17-جلسات و دوره‌ها'!$A$8:$A$1007,D51)=1,IFERROR(INDEX('17-جلسات و دوره‌ها'!$B$8:$B$1007,MATCH(D51,'17-جلسات و دوره‌ها'!$A$8:$A$1007,0)),"")=B51,IFERROR(INDEX('17-جلسات و دوره‌ها'!$C$8:$C$1007,MATCH(D51,'17-جلسات و دوره‌ها'!$A$8:$A$1007,0)),"")=C51))),"شناسه یا جلسه نامعتبر",IF(AND(M51="بررسی شد",J51<>"",O51<>"",P51<>"",Q51<>"",AND(COUNTIFS('14-مستندات و پیوست‌ها'!$A$8:$A$1007,L51)=1,IFERROR(INDEX('14-مستندات و پیوست‌ها'!$B$8:$B$1007,MATCH(L51,'14-مستندات و پیوست‌ها'!$A$8:$A$1007,0)),"")=B51,OR(IFERROR(INDEX('14-مستندات و پیوست‌ها'!$H$8:$H$1007,MATCH(L51,'14-مستندات و پیوست‌ها'!$A$8:$A$1007,0)),"")="دریافت شده",IFERROR(INDEX('14-مستندات و پیوست‌ها'!$H$8:$H$1007,MATCH(L51,'14-مستندات و پیوست‌ها'!$A$8:$A$1007,0)),"")="فرضی"))),"معتبر","بررسی یا شاهد ناقص")))

Sheet 04-تحلیل شاخص‌ها
A1: تحلیل شاخص‌ها و کنترل هدف مشتری
A2: هدف مشتری فقط پس از تأیید منشأ هدف و داده فعال می‌شود؛ هدف داخلی به‌طور خودکار هدف تعیین‌شده مشتری فرض نمی‌شود. صفر معتبر از داده مفقود جداست.
A7: شناسه شاخص | B7: شرکت | C7: دوره | D7: جلسه | E7: نوع داده | F7: شناسه ورودی | G7: فرآیند | H7: سیستم | I7: نام شاخص | J7: واحد | K7: جهت مطلوب | L7: هدف مصوب | M7: دوره قبل | N7: واقعی | O7: منشأ هدف | P7: مرجع داده و هدف | Q7: اعتبار داده | R7: انحراف از هدف | S7: تغییر نسبت قبل | T7: تحقق هدف | U7: برنامه مرتبط معتبر | V7: هشدار اجرایی | W7: تحلیل مالک
A8: KP-K01 | B8: NIPCO | C8: P-BASE | D8: MR-NIPCO-BASE | E8: واقعی؛ نیازمند تأیید | F8: IN-R27 | G8: HSE | H8: HSE | I8: ضریب تکرار حادثه | J8: مطابق منبع؛ تأیید شود | K8: تأیید نشده | L8: 30 | M8: 43 | N8: 35 | O8: تأیید نشده | P8: فایل پایش دریافت نشده؛ تطبیق با فایل پایش لازم است | Q8: نیازمند تطبیق | R8: =IF(A8="","",IF(AND(ISNUMBER(N8),ISNUMBER(L8)),N8-L8,"")) -> 5 | S8: =IF(A8="","",IF(AND(ISNUMBER(N8),ISNUMBER(M8)),N8-M8,"")) -> -8 | T8: =IF(A8="","",IF(NOT(AND(COUNTIFS('04-تحلیل شاخص‌ها'!$A$8:$A$1007,A8)=1,AND(COUNTIFS('17-جلسات و دوره‌ها'!$A$8:$A$1007,D8)=1,IFERROR(INDEX('17-جلسات و دوره‌ها'!$B$8:$B$1007,MATCH(D8,'17-جلسات و دوره‌ها'!$A$8:$A$1007,0)),"")=B8,IFERROR(INDEX('17-جلسات و دوره‌ها'!$C$8:$C$1007,MATCH(D8,'17-جلسات و دوره‌ها'!$A$8:$A$1007,0)),"")=C8),COUNTIFS('03-ورودی‌های بازنگری'!$A$8:$A$1007,F8)=1,IFERROR(INDEX('03-ورودی‌های بازنگری'!$D$8:$D$1007,MATCH(F8,'03-ورودی‌های بازنگری'!$A$8:$A$1007,0)),"")=D8)),"رابطه نامعتبر",IF(OR(Q8<>"تأیید شده",NOT(ISNUMBER(L8)),NOT(ISNUMBER(N8)),K8="تأیید نشده",P8=""),"نیازمند تأیید داده و هدف",IF(OR(AND(K8="کمتر بهتر",N8<=L8),AND(K8="بیشتر بهتر",N8>=L8),AND(K8="برابر هدف",N8=L8)),"محقق","محقق نشده")))) -> نیازمند تأیید داده و هدف | U8: =IF(A8="","",COUNTIFS('15-روابط'!$C$8:$C$1007,"ورودی",'15-روابط'!$D$8:$D$1007,F8,'15-روابط'!$E$8:$E$1007,"برنامه مصوب معتبر")) -> 0 | V8: =IF(A8="","",IF(T8<>"محقق نشده",T8,IF(O8="مشتری",IF(U8=0,"IATF: هدف مشتری؛ برنامه مصوب ندارد","برنامه مشتری ثبت شده؛ پایش اجرا لازم"),IF(O8="محیط‌زیستی",IF(U8=0,"هدف محیط‌زیستی؛ تعیین اقدام لازم","اقدام محیط‌زیستی ثبت شده"),"عدم تحقق؛ بررسی مدیریت لازم")))) -> نیازمند تأیید داده و هدف | W8: پیش از تصمیم، تعریف و دوره تأیید شود.
A9: KP-K02 | B9: NIPCO | C9: P-BASE | D9: MR-NIPCO-BASE | E9: واقعی؛ نیازمند تأیید | F9: IN-R27 | G9: HSE | H9: HSE | I9: ضریب شدت حادثه | J9: مطابق منبع؛ تأیید شود | K9: تأیید نشده | L9: 0.04 | M9: 0.07 | N9: 0.07 | O9: تأیید نشده | P9: فایل پایش دریافت نشده؛ تطبیق با فایل پایش لازم است | Q9: نیازمند تطبیق | R9: =IF(A9="","",IF(AND(ISNUMBER(N9),ISNUMBER(L9)),N9-L9,"")) -> 0.03 | S9: =IF(A9="","",IF(AND(ISNUMBER(N9),ISNUMBER(M9)),N9-M9,"")) -> 0 | T9: =IF(A9="","",IF(NOT(AND(COUNTIFS('04-تحلیل شاخص‌ها'!$A$8:$A$1007,A9)=1,AND(COUNTIFS('17-جلسات و دوره‌ها'!$A$8:$A$1007,D9)=1,IFERROR(INDEX('17-جلسات و دوره‌ها'!$B$8:$B$1007,MATCH(D9,'17-جلسات و دوره‌ها'!$A$8:$A$1007,0)),"")=B9,IFERROR(INDEX('17-جلسات و دوره‌ها'!$C$8:$C$1007,MATCH(D9,'17-جلسات و دوره‌ها'!$A$8:$A$1007,0)),"")=C9),COUNTIFS('03-ورودی‌های بازنگری'!$A$8:$A$1007,F9)=1,IFERROR(INDEX('03-ورودی‌های بازنگری'!$D$8:$D$1007,MATCH(F9,'03-ورودی‌های بازنگری'!$A$8:$A$1007,0)),"")=D9)),"رابطه نامعتبر",IF(OR(Q9<>"تأیید شده",NOT(ISNUMBER(L9)),NOT(ISNUMBER(N9)),K9="تأیید نشده",P9=""),"نیازمند تأیید داده و هدف",IF(OR(AND(K9="کمتر بهتر",N9<=L9),AND(K9="بیشتر بهتر",N9>=L9),AND(K9="برابر هدف",N9=L9)),"محقق","محقق نشده")))) -> نیازمند تأیید داده و هدف | U9: =IF(A9="","",COUNTIFS('15-روابط'!$C$8:$C$1007,"ورودی",'15-روابط'!$D$8:$D$1007,F9,'15-روابط'!$E$8:$E$1007,"برنامه مصوب معتبر")) -> 0 | V9: =IF(A9="","",IF(T9<>"محقق نشده",T9,IF(O9="مشتری",IF(U9=0,"IATF: هدف مشتری؛ برنامه مصوب ندارد","برنامه مشتری ثبت شده؛ پایش اجرا لازم"),IF(O9="محیط‌زیستی",IF(U9=0,"هدف محیط‌زیستی؛ تعیین اقدام لازم","اقدام محیط‌زیستی ثبت شده"),"عدم تحقق؛ بررسی مدیریت لازم")))) -> نیازمند تأیید داده و هدف | W9: پیش از تصمیم، تعریف و دوره تأیید شود.
A10: KP-K03 | B10: NIPCO | C10: P-BASE | D10: MR-NIPCO-BASE | E10: واقعی؛ نیازمند تأیید | F10: IN-R27 | G10: HSE | H10: HSE | I10: درصد انطباق کل ایمنی و بهداشت با الزامات | J10: مطابق منبع؛ تأیید شود | K10: تأیید نشده | L10: 95 | M10: 83 | N10: 83 | O10: تأیید نشده | P10: فایل پایش دریافت نشده؛ با حدود ۵۰٪ گزارش 5S؛ دامنه‌ها روشن شود | Q10: نیازمند تطبیق | R10: =IF(A10="","",IF(AND(ISNUMBER(N10),ISNUMBER(L10)),N10-L10,"")) -> -12 | S10: =IF(A10="","",IF(AND(ISNUMBER(N10),ISNUMBER(M10)),N10-M10,"")) -> 0 | T10: =IF(A10="","",IF(NOT(AND(COUNTIFS('04-تحلیل شاخص‌ها'!$A$8:$A$1007,A10)=1,AND(COUNTIFS('17-جلسات و دوره‌ها'!$A$8:$A$1007,D10)=1,IFERROR(INDEX('17-جلسات و دوره‌ها'!$B$8:$B$1007,MATCH(D10,'17-جلسات و دوره‌ها'!$A$8:$A$1007,0)),"")=B10,IFERROR(INDEX('17-جلسات و دوره‌ها'!$C$8:$C$1007,MATCH(D10,'17-جلسات و دوره‌ها'!$A$8:$A$1007,0)),"")=C10),COUNTIFS('03-ورودی‌های بازنگری'!$A$8:$A$1007,F10)=1,IFERROR(INDEX('03-ورودی‌های بازنگری'!$D$8:$D$1007,MATCH(F10,'03-ورودی‌های بازنگری'!$A$8:$A$1007,0)),"")=D10)),"رابطه نامعتبر",IF(OR(Q10<>"تأیید شده",NOT(ISNUMBER(L10)),NOT(ISNUMBER(N10)),K10="تأیید نشده",P10=""),"نیازمند تأیید داده و هدف",IF(OR(AND(K10="کمتر بهتر",N10<=L10),AND(K10="بیشتر بهتر",N10>=L10),AND(K10="برابر هدف",N10=L10)),"محقق","محقق نشده")))) -> نیازمند تأیید داده و هدف | U10: =IF(A10="","",COUNTIFS('15-روابط'!$C$8:$C$1007,"ورودی",'15-روابط'!$D$8:$D$1007,F10,'15-روابط'!$E$8:$E$1007,"برنامه مصوب معتبر")) -> 0 | V10: =IF(A10="","",IF(T10<>"محقق نشده",T10,IF(O10="مشتری",IF(U10=0,"IATF: هدف مشتری؛ برنامه مصوب ندارد","برنامه مشتری ثبت شده؛ پایش اجرا لازم"),IF(O10="محیط‌زیستی",IF(U10=0,"هدف محیط‌زیستی؛ تعیین اقدام لازم","اقدام محیط‌زیستی ثبت شده"),"عدم تحقق؛ بررسی مدیریت لازم")))) -> نیازمند تأیید داده و هدف | W10: پیش از تصمیم، تعریف و دوره تأیید شود.
A11: KP-K04 | B11: NIPCO | C11: P-BASE | D11: MR-NIPCO-BASE | E11: واقعی؛ نیازمند تأیید | F11: IN-R27 | G11: HSE | H11: HSE | I11: درصد انطباق کل زیست محیطی با الزامات | J11: مطابق منبع؛ تأیید شود | K11: تأیید نشده | L11: 90 | M11: 83 | N11: 86 | O11: تأیید نشده | P11: فایل پایش دریافت نشده؛ با حدود ۵۰٪ گزارش 5S؛ دامنه‌ها روشن شود | Q11: نیازمند تطبیق | R11: =IF(A11="","",IF(AND(ISNUMBER(N11),ISNUMBER(L11)),N11-L11,"")) -> -4 | S11: =IF(A11="","",IF(AND(ISNUMBER(N11),ISNUMBER(M11)),N11-M11,"")) -> 3 | T11: =IF(A11="","",IF(NOT(AND(COUNTIFS('04-تحلیل شاخص‌ها'!$A$8:$A$1007,A11)=1,AND(COUNTIFS('17-جلسات و دوره‌ها'!$A$8:$A$1007,D11)=1,IFERROR(INDEX('17-جلسات و دوره‌ها'!$B$8:$B$1007,MATCH(D11,'17-جلسات و دوره‌ها'!$A$8:$A$1007,0)),"")=B11,IFERROR(INDEX('17-جلسات و دوره‌ها'!$C$8:$C$1007,MATCH(D11,'17-جلسات و دوره‌ها'!$A$8:$A$1007,0)),"")=C11),COUNTIFS('03-ورودی‌های بازنگری'!$A$8:$A$1007,F11)=1,IFERROR(INDEX('03-ورودی‌های بازنگری'!$D$8:$D$1007,MATCH(F11,'03-ورودی‌های بازنگری'!$A$8:$A$1007,0)),"")=D11)),"رابطه نامعتبر",IF(OR(Q11<>"تأیید شده",NOT(ISNUMBER(L11)),NOT(ISNUMBER(N11)),K11="تأیید نشده",P11=""),"نیازمند تأیید داده و هدف",IF(OR(AND(K11="کمتر بهتر",N11<=L11),AND(K11="بیشتر بهتر",N11>=L11),AND(K11="برابر هدف",N11=L11)),"محقق","محقق نشده")))) -> نیازمند تأیید داده و هدف | U11: =IF(A11="","",COUNTIFS('15-روابط'!$C$8:$C$1007,"ورودی",'15-روابط'!$D$8:$D$1007,F11,'15-روابط'!$E$8:$E$1007,"برنامه مصوب معتبر")) -> 0 | V11: =IF(A11="","",IF(T11<>"محقق نشده",T11,IF(O11="مشتری",IF(U11=0,"IATF: هدف مشتری؛ برنامه مصوب ندارد","برنامه مشتری ثبت شده؛ پایش اجرا لازم"),IF(O11="محیط‌زیستی",IF(U11=0,"هدف محیط‌زیستی؛ تعیین اقدام لازم","اقدام محیط‌زیستی ثبت شده"),"عدم تحقق؛ بررسی مدیریت لازم")))) -> نیازمند تأیید داده و هدف | W11: پیش از تصمیم، تعریف و دوره تأیید شود.
A12: KP-K05 | B12: NIPCO | C12: P-BASE | D12: MR-NIPCO-BASE | E12: واقعی؛ نیازمند تأیید | F12: IN-R27 | G12: HSE | H12: HSE | I12: میانگین درصد مشارکت و مشاوره کارکنان (واحدها) | J12: مطابق منبع؛ تأیید شود | K12: تأیید نشده | L12: 80 | M12: 71 | N12: 83 | O12: تأیید نشده | P12: فایل پایش دریافت نشده؛ تطبیق با فایل پایش لازم است | Q12: نیازمند تطبیق | R12: =IF(A12="","",IF(AND(ISNUMBER(N12),ISNUMBER(L12)),N12-L12,"")) -> 3 | S12: =IF(A12="","",IF(AND(ISNUMBER(N12),ISNUMBER(M12)),N12-M12,"")) -> 12 | T12: =IF(A12="","",IF(NOT(AND(COUNTIFS('04-تحلیل شاخص‌ها'!$A$8:$A$1007,A12)=1,AND(COUNTIFS('17-جلسات و دوره‌ها'!$A$8:$A$1007,D12)=1,IFERROR(INDEX('17-جلسات و دوره‌ها'!$B$8:$B$1007,MATCH(D12,'17-جلسات و دوره‌ها'!$A$8:$A$1007,0)),"")=B12,IFERROR(INDEX('17-جلسات و دوره‌ها'!$C$8:$C$1007,MATCH(D12,'17-جلسات و دوره‌ها'!$A$8:$A$1007,0)),"")=C12),COUNTIFS('03-ورودی‌های بازنگری'!$A$8:$A$1007,F12)=1,IFERROR(INDEX('03-ورودی‌های بازنگری'!$D$8:$D$1007,MATCH(F12,'03-ورودی‌های بازنگری'!$A$8:$A$1007,0)),"")=D12)),"رابطه نامعتبر",IF(OR(Q12<>"تأیید شده",NOT(ISNUMBER(L12)),NOT(ISNUMBER(N12)),K12="تأیید نشده",P12=""),"نیازمند تأیید داده و هدف",IF(OR(AND(K12="کمتر بهتر",N12<=L12),AND(K12="بیشتر بهتر",N12>=L12),AND(K12="برابر هدف",N12=L12)),"محقق","محقق نشده")))) -> نیازمند تأیید داده و هدف | U12: =IF(A12="","",COUNTIFS('15-روابط'!$C$8:$C$1007,"ورودی",'15-روابط'!$D$8:$D$1007,F12,'15-روابط'!$E$8:$E$1007,"برنامه مصوب معتبر")) -> 0 | V12: =IF(A12="","",IF(T12<>"محقق نشده",T12,IF(O12="مشتری",IF(U12=0,"IATF: هدف مشتری؛ برنامه مصوب ندارد","برنامه مشتری ثبت شده؛ پایش اجرا لازم"),IF(O12="محیط‌زیستی",IF(U12=0,"هدف محیط‌زیستی؛ تعیین اقدام لازم","اقدام محیط‌زیستی ثبت شده"),"عدم تحقق؛ بررسی مدیریت لازم")))) -> نیازمند تأیید داده و هدف | W12: پیش از تصمیم، تعریف و دوره تأیید شود.
A13: KP-K06 | B13: NIPCO | C13: P-BASE | D13: MR-NIPCO-BASE | E13: واقعی؛ نیازمند تأیید | F13: IN-R27 | G13: HSE | H13: HSE | I13: درصد انطباق اندازه گیری آلاینده های محیط کار | J13: مطابق منبع؛ تأیید شود | K13: تأیید نشده | L13: 95 | M13: 91.45 | N13: 95.73 | O13: تأیید نشده | P13: فایل پایش دریافت نشده؛ تطبیق با فایل پایش لازم است | Q13: نیازمند تطبیق | R13: =IF(A13="","",IF(AND(ISNUMBER(N13),ISNUMBER(L13)),N13-L13,"")) -> 0.73 | S13: =IF(A13="","",IF(AND(ISNUMBER(N13),ISNUMBER(M13)),N13-M13,"")) -> 4.28 | T13: =IF(A13="","",IF(NOT(AND(COUNTIFS('04-تحلیل شاخص‌ها'!$A$8:$A$1007,A13)=1,AND(COUNTIFS('17-جلسات و دوره‌ها'!$A$8:$A$1007,D13)=1,IFERROR(INDEX('17-جلسات و دوره‌ها'!$B$8:$B$1007,MATCH(D13,'17-جلسات و دوره‌ها'!$A$8:$A$1007,0)),"")=B13,IFERROR(INDEX('17-جلسات و دوره‌ها'!$C$8:$C$1007,MATCH(D13,'17-جلسات و دوره‌ها'!$A$8:$A$1007,0)),"")=C13),COUNTIFS('03-ورودی‌های بازنگری'!$A$8:$A$1007,F13)=1,IFERROR(INDEX('03-ورودی‌های بازنگری'!$D$8:$D$1007,MATCH(F13,'03-ورودی‌های بازنگری'!$A$8:$A$1007,0)),"")=D13)),"رابطه نامعتبر",IF(OR(Q13<>"تأیید شده",NOT(ISNUMBER(L13)),NOT(ISNUMBER(N13)),K13="تأیید نشده",P13=""),"نیازمند تأیید داده و هدف",IF(OR(AND(K13="کمتر بهتر",N13<=L13),AND(K13="بیشتر بهتر",N13>=L13),AND(K13="برابر هدف",N13=L13)),"محقق","محقق نشده")))) -> نیازمند تأیید داده و هدف | U13: =IF(A13="","",COUNTIFS('15-روابط'!$C$8:$C$1007,"ورودی",'15-روابط'!$D$8:$D$1007,F13,'15-روابط'!$E$8:$E$1007,"برنامه مصوب معتبر")) -> 0 | V13: =IF(A13="","",IF(T13<>"محقق نشده",T13,IF(O13="مشتری",IF(U13=0,"IATF: هدف مشتری؛ برنامه مصوب ندارد","برنامه مشتری ثبت شده؛ پایش اجرا لازم"),IF(O13="محیط‌زیستی",IF(U13=0,"هدف محیط‌زیستی؛ تعیین اقدام لازم","اقدام محیط‌زیستی ثبت شده"),"عدم تحقق؛ بررسی مدیریت لازم")))) -> نیازمند تأیید داده و هدف | W13: پیش از تصمیم، تعریف و دوره تأیید شود.
A14: KP-K07 | B14: NIPCO | C14: P-BASE | D14: MR-NIPCO-BASE | E14: واقعی؛ نیازمند تأیید | F14: IN-R27 | G14: HSE | H14: HSE | I14: درصد انطباق اندازه گیری زیست محیطی | J14: مطابق منبع؛ تأیید شود | K14: تأیید نشده | L14: 90 | M14: 76 | N14: 96.2 | O14: تأیید نشده | P14: فایل پایش دریافت نشده؛ تطبیق با فایل پایش لازم است | Q14: نیازمند تطبیق | R14: =IF(A14="","",IF(AND(ISNUMBER(N14),ISNUMBER(L14)),N14-L14,"")) -> 6.2 | S14: =IF(A14="","",IF(AND(ISNUMBER(N14),ISNUMBER(M14)),N14-M14,"")) -> 20.2 | T14: =IF(A14="","",IF(NOT(AND(COUNTIFS('04-تحلیل شاخص‌ها'!$A$8:$A$1007,A14)=1,AND(COUNTIFS('17-جلسات و دوره‌ها'!$A$8:$A$1007,D14)=1,IFERROR(INDEX('17-جلسات و دوره‌ها'!$B$8:$B$1007,MATCH(D14,'17-جلسات و دوره‌ها'!$A$8:$A$1007,0)),"")=B14,IFERROR(INDEX('17-جلسات و دوره‌ها'!$C$8:$C$1007,MATCH(D14,'17-جلسات و دوره‌ها'!$A$8:$A$1007,0)),"")=C14),COUNTIFS('03-ورودی‌های بازنگری'!$A$8:$A$1007,F14)=1,IFERROR(INDEX('03-ورودی‌های بازنگری'!$D$8:$D$1007,MATCH(F14,'03-ورودی‌های بازنگری'!$A$8:$A$1007,0)),"")=D14)),"رابطه نامعتبر",IF(OR(Q14<>"تأیید شده",NOT(ISNUMBER(L14)),NOT(ISNUMBER(N14)),K14="تأیید نشده",P14=""),"نیازمند تأیید داده و هدف",IF(OR(AND(K14="کمتر بهتر",N14<=L14),AND(K14="بیشتر بهتر",N14>=L14),AND(K14="برابر هدف",N14=L14)),"محقق","محقق نشده")))) -> نیازمند تأیید داده و هدف | U14: =IF(A14="","",COUNTIFS('15-روابط'!$C$8:$C$1007,"ورودی",'15-روابط'!$D$8:$D$1007,F14,'15-روابط'!$E$8:$E$1007,"برنامه مصوب معتبر")) -> 0 | V14: =IF(A14="","",IF(T14<>"محقق نشده",T14,IF(O14="مشتری",IF(U14=0,"IATF: هدف مشتری؛ برنامه مصوب ندارد","برنامه مشتری ثبت شده؛ پایش اجرا لازم"),IF(O14="محیط‌زیستی",IF(U14=0,"هدف محیط‌زیستی؛ تعیین اقدام لازم","اقدام محیط‌زیستی ثبت شده"),"عدم تحقق؛ بررسی مدیریت لازم")))) -> نیازمند تأیید داده و هدف | W14: پیش از تصمیم، تعریف و دوره تأیید شود.
A15: KP-K08 | B15: NIPCO | C15: P-BASE | D15: MR-NIPCO-BASE | E15: واقعی؛ نیازمند تأیید | F15: IN-R27 | G15: HSE | H15: HSE | I15: درصد انطباق با قوانین ایمنی | J15: مطابق منبع؛ تأیید شود | K15: تأیید نشده | L15: 95 | M15: 90 | N15: 90 | O15: تأیید نشده | P15: فایل پایش دریافت نشده؛ تطبیق با فایل پایش لازم است | Q15: نیازمند تطبیق | R15: =IF(A15="","",IF(AND(ISNUMBER(N15),ISNUMBER(L15)),N15-L15,"")) -> -5 | S15: =IF(A15="","",IF(AND(ISNUMBER(N15),ISNUMBER(M15)),N15-M15,"")) -> 0 | T15: =IF(A15="","",IF(NOT(AND(COUNTIFS('04-تحلیل شاخص‌ها'!$A$8:$A$1007,A15)=1,AND(COUNTIFS('17-جلسات و دوره‌ها'!$A$8:$A$1007,D15)=1,IFERROR(INDEX('17-جلسات و دوره‌ها'!$B$8:$B$1007,MATCH(D15,'17-جلسات و دوره‌ها'!$A$8:$A$1007,0)),"")=B15,IFERROR(INDEX('17-جلسات و دوره‌ها'!$C$8:$C$1007,MATCH(D15,'17-جلسات و دوره‌ها'!$A$8:$A$1007,0)),"")=C15),COUNTIFS('03-ورودی‌های بازنگری'!$A$8:$A$1007,F15)=1,IFERROR(INDEX('03-ورودی‌های بازنگری'!$D$8:$D$1007,MATCH(F15,'03-ورودی‌های بازنگری'!$A$8:$A$1007,0)),"")=D15)),"رابطه نامعتبر",IF(OR(Q15<>"تأیید شده",NOT(ISNUMBER(L15)),NOT(ISNUMBER(N15)),K15="تأیید نشده",P15=""),"نیازمند تأیید داده و هدف",IF(OR(AND(K15="کمتر بهتر",N15<=L15),AND(K15="بیشتر بهتر",N15>=L15),AND(K15="برابر هدف",N15=L15)),"محقق","محقق نشده")))) -> نیازمند تأیید داده و هدف | U15: =IF(A15="","",COUNTIFS('15-روابط'!$C$8:$C$1007,"ورودی",'15-روابط'!$D$8:$D$1007,F15,'15-روابط'!$E$8:$E$1007,"برنامه مصوب معتبر")) -> 0 | V15: =IF(A15="","",IF(T15<>"محقق نشده",T15,IF(O15="مشتری",IF(U15=0,"IATF: هدف مشتری؛ برنامه مصوب ندارد","برنامه مشتری ثبت شده؛ پایش اجرا لازم"),IF(O15="محیط‌زیستی",IF(U15=0,"هدف محیط‌زیستی؛ تعیین اقدام لازم","اقدام محیط‌زیستی ثبت شده"),"عدم تحقق؛ بررسی مدیریت لازم")))) -> نیازمند تأیید داده و هدف | W15: پیش از تصمیم، تعریف و دوره تأیید شود.
A16: KP-K09 | B16: NIPCO | C16: P-BASE | D16: MR-NIPCO-BASE | E16: واقعی؛ نیازمند تأیید | F16: IN-R27 | G16: HSE | H16: HSE | I16: درصد انطباق با قوانین زیست محیطی | J16: مطابق منبع؛ تأیید شود | K16: تأیید نشده | L16: 90 | M16: 80 | N16: 80 | O16: تأیید نشده | P16: فایل پایش دریافت نشده؛ تطبیق با فایل پایش لازم است | Q16: نیازمند تطبیق | R16: =IF(A16="","",IF(AND(ISNUMBER(N16),ISNUMBER(L16)),N16-L16,"")) -> -10 | S16: =IF(A16="","",IF(AND(ISNUMBER(N16),ISNUMBER(M16)),N16-M16,"")) -> 0 | T16: =IF(A16="","",IF(NOT(AND(COUNTIFS('04-تحلیل شاخص‌ها'!$A$8:$A$1007,A16)=1,AND(COUNTIFS('17-جلسات و دوره‌ها'!$A$8:$A$1007,D16)=1,IFERROR(INDEX('17-جلسات و دوره‌ها'!$B$8:$B$1007,MATCH(D16,'17-جلسات و دوره‌ها'!$A$8:$A$1007,0)),"")=B16,IFERROR(INDEX('17-جلسات و دوره‌ها'!$C$8:$C$1007,MATCH(D16,'17-جلسات و دوره‌ها'!$A$8:$A$1007,0)),"")=C16),COUNTIFS('03-ورودی‌های بازنگری'!$A$8:$A$1007,F16)=1,IFERROR(INDEX('03-ورودی‌های بازنگری'!$D$8:$D$1007,MATCH(F16,'03-ورودی‌های بازنگری'!$A$8:$A$1007,0)),"")=D16)),"رابطه نامعتبر",IF(OR(Q16<>"تأیید شده",NOT(ISNUMBER(L16)),NOT(ISNUMBER(N16)),K16="تأیید نشده",P16=""),"نیازمند تأیید داده و هدف",IF(OR(AND(K16="کمتر بهتر",N16<=L16),AND(K16="بیشتر بهتر",N16>=L16),AND(K16="برابر هدف",N16=L16)),"محقق","محقق نشده")))) -> نیازمند تأیید داده و هدف | U16: =IF(A16="","",COUNTIFS('15-روابط'!$C$8:$C$1007,"ورودی",'15-روابط'!$D$8:$D$1007,F16,'15-روابط'!$E$8:$E$1007,"برنامه مصوب معتبر")) -> 0 | V16: =IF(A16="","",IF(T16<>"محقق نشده",T16,IF(O16="مشتری",IF(U16=0,"IATF: هدف مشتری؛ برنامه مصوب ندارد","برنامه مشتری ثبت شده؛ پایش اجرا لازم"),IF(O16="محیط‌زیستی",IF(U16=0,"هدف محیط‌زیستی؛ تعیین اقدام لازم","اقدام محیط‌زیستی ثبت شده"),"عدم تحقق؛ بررسی مدیریت لازم")))) -> نیازمند تأیید داده و هدف | W16: پیش از تصمیم، تعریف و دوره تأیید شود.
