Workbook

Sheet 21
C1: فرم بازنگری مدیریت | N1: تاریخ | O1: ='1'!O1 -> 1405/05/22
N2: صفحه | O2: 21
A3: خروجی بازنگری مدیریت | N3: مسئول | O3: تاریخ
C5: شاخصهای لجستیکی | N5: مدیریت ، برنامه ریزی | O5: 1405/12
A6: مالی - انبار | C6: گردش مالی موجودی (ITR) سال 1402 انبار محصول=117.85 سالیانه | N6: مالی/فروش
A7: برنامه ریزی | C7: تحویل به موقع هدف (OTD)= 100% | H7: 95.11 | N7: فروش | O7: پیوسته
A8: مهندسی | C8: زمانهای انتظار لجستیکی . در برگه های فرایند لحاظ گردیده است ولی به مرحله پایش نرسیده است. ( اجرا نگردیده است ) | N8: مهندسی - تولید | O8: 1405/12
A9: انحراف از برنامه تولید | C9: تحقق برنامه تولید = 88/29 | N9: برنامه ریزی | O9: پیوسته
A10: هزینه های لجستکی | C10: با توجه به نبود زیر ساختهای لجستیکی مالی نیاز به ایجاد زیر ساخت دارد | N10: مالی | O10: 1405/12
A18: شماره فرم : MA-F-19 | D18: شماره بروزرسانی : 0 | J18: تاریخ بروز رسانی : 99/05/10

Sheet 20
C1: فرم بازنگری مدیریت | N1: تاریخ | O1: ='1'!O1 -> 1405/05/22
N2: صفحه | O2: 20
A3: خروجی بازنگری مدیریت | N3: مسئول | O3: تاریخ
A5: مدیریت برنامه ریزی | C5: پیگیری ساخت رک و پالت جهت محصولات مایان و ریرا | N5: مدیریت ، برنامه ریزی | O5: 1405/12
A6: منابع انسانی | C6: مدیریت گزینش اپراتور تولیدی خصوصا 6 ماهه دوم سال و خصوصا سه ماهه زمستان - در سه شیفت نیاز به 12 نفر نیرو جهت امور ربات و موارد مختلف است | N6: منابع انسانی | O6: 1405/12
A7: منابع انسانی | C7: تدوین برنامه مدونی با چشم انداز چند ساله برای تقویت و ارتقا پرسنل های چند مهارتی/ در صورت امکان job rotation | N7: منابع انسانی | O7: 1405/12
C8: افزایش مهارت نیروی انسانی در خصوص نکات خاص لجستیکی و زمانهای انتظار و اقتصادی بودن پالتها و انباشتهای بین ایستگاهی و انبارهای مواد اولیه و محصول آموزش موارد آدیت لایه ای ،FR جهت پرسنل تولیدی جهت توانمند سازی منابع انسانی تولیدی | N8: منابع انسانی
A9: نیازمندی های منابع با توجه به چشم انداز سال 1405 | C9: خریداری سه عدد ربات و انتقال به کارخانه سایت 1(به منظور افزایش ظرفیت تولید و کاهش زمان های انتظار و هزینه های کیفی) | N9: بازرگانی /مهندسی | O9: 1405/12
C10: ساخت قالب دوم برای قطعات تک قالب جهت کاهش ریسک توقف تولید(- قالب سینی فن دنا ( دنا معمولی /دناپلاس ) -- قالب بیم تقویتی کوییک - قالب سینی فن 206 .) | N10: تحقیق و توسعه /بازرگانی /مهندسی | O10: 1405/12
C11: ساخت به طور متوسط 40 پالت در ماه ( با توجه به کاهش سفارش مشتری براساس پیش بینی فروش مهرماه 1402 متوقف گردیده است ) | N11: بازرگانی(تدارکات) | O11: 1405/12
C12: تکمیل ساخت فضای انبار نیم ساخته/ مواد اولیه مربوط به سایت 2 | N12: مدیریت سایت 2 | O12: 1405/12
C13: تکمیلفرآیند خریداری و نصب پرس پانچ سوم مربوط به سایت 2 | N13: مدیریت سایت 2 | O13: 1405/12
C14: تشکیل کمیته 5S و اجرای آن/ جذب کارمند آموزش | N14: منابع | O14: 1405/12
A17: شماره فرم : MA-F-19 | D17: شماره بروزرسانی : 0 | J17: تاریخ بروز رسانی : 99/05/10

Sheet 19
C1: فرم بازنگری مدیریت | N1: تاریخ | O1: ='1'!O1 -> 1405/05/22
N2: صفحه | O2: 19
A3: ورودی بازنگری مدیریت | C3: هدف | D3: معیار پذیرش | E3: شاخص دوره قبل | F3: شاخص این دوره | G3: تحلیل و بررسی | K3: اقدام پیشنهادی/منابع مورد نیاز | N3: مسئول | O3: تاریخ
A5: بسته بندی و برچسب زنی | C5: قابلیت ردیابی از بعد از انجام عملیات پرس ناقص می باشد و قرار شده با خرید کامپیوتر در خط تولید مورد مذکور و گزارشات تولیدی اتوماسیون شود. محصولات شرکت از مواد اولیه برچسب شناسایی خورده و بعد از اولین مرحله تولید ( پرس) بارکد روی محصول نصب می شود و تا محصول نهایی بارکد روی محصول تا رسیدن دست مشتری حفظ می شود . بارکدها یکه می باشد . محصول در سایر مراحل تولید توسط پالت مخصوص حمل شده و توسط برگ سفر قابل ردیابی و تعیین وضعیت می باشد. در مرحله بسته بندی بصورت کامل تمیز شده با حفظ بارکد تحویل انبار محصول نهایی می شود . | O5: پیوسته
N6: تولید
A8: حمل و نقل | C8: حمل و نقل از قسمت اعظم مواد اولیه تا انبار محصول نهایی توسط خود شرکت صورت می گیرد . از انبار محصول نهایی برای مونتاژ یا مشتری قسمتی توسط خود شرکت و قسمتی توسط حاملهای حائز شرایط صورت می گیرد . با توجه به اینکه بیشتر زنجیره تامین از مواد اولیه تا محصول نهایی توسط شرکتهای هلدینگ صورت می گیرد لذا فرایند یکپارچه سازی و استفاددر خصوص بحث حمل و نقل مشکل سوخت خودروهای سنگین است که در حال حاد شدن است. و در حال اندیشیدن تمهیداتی جهت تسهیل مورد فوق . البته ظاهرا موضوع کشوری است.ه از ظرفیت کامل حامل به خوبی استفاده می شود. | O8: پیوسته
N9: تامین - فروش
A11: دریافت و ارسال | C11: دریافت و ارسال توسط انبار مواد اولیه و انبار محصول نهایی صورت می گیرد . بار انداز دریافت و ارسال در محل شرکت جهت تخلیه و بارگیری در دو محل جداگانه صورت می گیرد و تداخل ورود و خروج به بارانداز زمان بارگیری و تخلیه ندارد و نیروهای دریافت و ارسال مستقل عمل می کنند . دریافت زیر نظر برنامه ریزی صورت می گیرد و ارسال تحت نظر فروش می باشد و در این زمینه حتی تداخل مدیریت ندارد . جهت میزان تولید و ارسال به انبار محصول نهایی همانطور که قبلا گفته شد . سیاست تولید کانبانی نیست و بصورت تولید انبوه می باشد. دریافت کالا ها از طریف انبار محصول و مواد اولیه هنگام دریافت و ارسال نیاز به چک لیست دریافت و ارسال دارد . الزامات لجستیکی ساپکو . زمانهای بارگیری و تخلیه و منابع آنها قابل ارزیابی و تعیین کفایت نمی کند . کار صورت می گیرد ولی قابل ارزیابی نیست. | N11: برنامه ریزی و فروش | O11: پیوسته
A17: انبارش و نگهداری | C17: هر یک از مواد اولیه و محصول با توجه به شرایط تعریف شده از طرف واحد مهندسی . بصورت کاملا علمی و تحت کنترل طبق دستورالعمل چیدمان و انبارش نگهداری و حفظ می شوند . جهت موارد حاد که تولید با توجه به دستور مدیریت و برنامه ریزی بصورت انبوه می باشد. با هماهنگی از طرح های اقتضایی استفاده می شود . با توجه به تحویل به موقع بالا و شرایط مطلوب شاخص فوق این شرکت توانسته از بین تامین کنندگان به موقعیت برتری دست یابد .و با توجه به انواع ریسکهای تولیدی و حمل و نقل امتیاز صددرصد را نصیب خود نماید. انبارش و نگهداری کالا و مواد اولیه شرایط مطلوبی دارد ولی نیاز به یک روش جهت ارزیابی سنجش منابع دارد . | N17: تولید - برنامه ریزی - فروش | O17: پیوسته
A22: شماره فرم : MA-F-19 | D22: شماره بروزرسانی : 0 | J22: تاریخ بروز رسانی : 99/05/10

Sheet 18
C1: فرم بازنگری مدیریت | N1: تاریخ | O1: ='1'!O1 -> 1405/05/22
N2: صفحه | O2: 18
A3: ورودی بازنگری مدیریت | C3: هدف | D3: معیار پذیرش | E3: شاخص دوره قبل | F3: شاخص این دوره | G3: تحلیل و بررسی | K3: اقدام پیشنهادی/منابع مورد نیاز | N3: مسئول | O3: تاریخ
A5: ریسک | C5: در خصوص موارد مرتبط با ریسکها طرحهای مختلف اقتضایی پیش بینی شده . خصوصا در مورد قطع برق ژنراتور تهیه شده که بمحض قطع جریان برق وارد مدار شده و به میزان تولید لطمه وارد نمی شود . در مورد سایر موارد از قبیل لیفتراک و منابع انسانی و انواع حامل ها پیش بینی های لازم صورت گرفته است . ریسک حملات سایبری که هنوز به مرحله قابل قبولی نرسیده و در حال پیگیری می باشد. | N5: صاحب فرایندها | O5: پیوسته
N6: تولید
A8: ریسک برنامه ریزی | C8: تبدیل تولید کششی به انبوه (MASS PRODUCTION ) به این روش انبار محصول نهایی همیشه بیشتر از موجودی برای ارسال خواهد داشت و در صورت ایجاد مشکل در تولید ، این انباشته میتواند برای تحویل به موقع مناسب باشد.ریسک فضای انبارش که با توجه به افزودن فضای شرقی قابل جبران است. و در حال انجام. شرکت ایمن ایستا به شرکت نیپکو اضافه می شود | N8: برنامه ریزی و مدیریت | O8: پیوسته
A11: تولید و کنترل محصول | C11: با توجه به اهمیت تولید و منابع مورد نیاز آن تمهیدات لازم از قبیل لجستیک داخلی و پالتها و رک های مخصوص طراحی شده و ایستگاه به ایستگاه شناسایی و تعیین وضعیت محصول بخوبی انجام می شود و زمانهای انتظار محاسبه شده و در برگه های فرایند آورده شده است. بعنوان مثال 1200 ثانیه زمان ورود مواد اولیه تا رسیدن به انبار محصول نهایی می باشد . بر اساس تولید یک محصول و متوسط زمانهای ایستگاهی تولید و انتظار . کمبود منابع انسانی بارز ترین عامل ریسک تولید است و با تمهیدات اندیشیده شده برای نگهداشت نیروی جذب شده در حال جبران است ولی اثربخشی لازم راندارد. | N11: برنامه ریزی و مدیریت | O11: پیوسته
A17: برنامه ریزی تامین | C17: با توجه به گستردگی دامنه تولید محصولات یکپارچگی تامین و زنجیره آن اهمیت زیادی داشته و قسمت اصلی زنجیره در هلدینگ می باشد . بطور مثال جریان ماده اصلی سینی فن که SMC می باشد بصورت روزانه محموله ها از شرکت پایاپلاست ایرانیان وارد شرکت می شود . لجستیک خارجی توسط خود شرکت صورت می گیرد و با توجه به نزدیکی تامین کننده قادر به انجام ورود محموله بصورت حتی برخط می باشد. یا اغلب موارد مونتاژی شرکت نیپکو در خود شهر صنعتی اشتهارد تامین می شود و توسط امکانات لجستیکی خود شرکت صورت می گیرد. ارزیابی تامین کنندگان و ساختار تامین کننده یک ریسک می باشد که بعلت کمبود نیروی کارشناسی در شرکت اصلی در واحد خرید مورد مذکور با تعلل روبرو است. | N17: تامین | O17: پیوسته
A22: شماره فرم : MA-F-19 | D22: شماره بروزرسانی : 0 | J22: تاریخ بروز رسانی : 99/05/10

Sheet 17
C1: فرم بازنگری مدیریت | N1: تاریخ | O1: ='1'!O1 -> 1405/05/22
N2: صفحه | O2: 17
A3: ورودی بازنگری مدیریت | C3: هدف | D3: معیار پذیرش | E3: شاخص دوره قبل | F3: شاخص این دوره | G3: تحلیل و بررسی | K3: اقدام پیشنهادی/منابع مورد نیاز | N3: مسئول | O3: تاریخ
C5: بازنگری مدیریت بر اساس الزامات خاص لجستیک ساپکو
A6: بینش ، راهبرد | C6: مستند سازی الزامات لجستیک ساپکو | N6: صاحب فرایندها | O6: 1405/12
C7: تدوین فرایندها بصورت فلوچارت در خصوص فرایندهایی که بیشترین ارتباط با موارد لجستیکی دارند . فرایند مسئولیت مدیریت ، فروش ، انبارهای مواد اولیه و محصول که دریافت و ارسال را شامل می شوند . فرایند برنامه ریزی ، خرید و تدارکات و تولید
C9: ادامه بازنگری روشهای اجرا ئی و دستورالعملها در راستای پوشش الزامات لجستیکی ساپکو و
C10: ورژن دوم ISSR-V2 که در دست اقدام می باشد.
A11: اطلاعات فروش | C11: بر اساس پیش بینی فروش | F11: 483192 | G11: SMC= | H11: 1211352 | I11: LFT= | J11: پیش بینی تعداد روزهای کاری | M11: 231
C12: تعداد پالتهای ارسالی | E12: 81952 | F12: تداد پالتهای دریافتی | H12: 81651 | I12: نیازمندی پالتهای در جریان بصورت امانی | L12: 301 | M12: پالت
A13: منابع برنامه ریزی | C13: طبق اطلاعات واحد برنامه ریزی | N13: برنامه ریزی و مدیریت | O13: 1405/12
C14: تعداد تولید | D14: 637025 | E14: SMC= | F14: 646522 | G14: LFT= | H14: برای سال 1405 | J14: تعداد روزهای مورد نیاز | M14: 311=
C15: متوسط حضور پرسنل تولید 144 نفر برای سال 1404 نیاز است که کسری با توجه به اضافه کاری برطرف می شود. ولی در شش ماهه دوم نیاز به افزایش پرسنل تولیدی متوسط 171 نفر خواهد بود .کسری نیروی با افزایش روزهای کاری قابل جبران می باشدو
C16: پالت تراک از طریق پیمانکاران در حال ساخت می باشد .
C17: قرار بر این شد تا پایان اردیبهشت سال 1406 شرکت ایمن ایستا در ضلع شرقی به شرکت نیپکو اضافه شود.
C20: منابع انسانی عامل کاهش تولید است و تمهیدات زیادی اندیشده شده ولی کماکان مشکل ادامه دارد و یک موضوع کشوری است.
A21: شماره فرم : MA-F-19 | D21: شماره بروزرسانی : 0 | J21: تاریخ بروز رسانی : 99/05/10

Sheet 15
C1: فرم بازنگری مدیریت | N1: تاریخ | O1: ='1'!O1 -> 1405/05/22
N2: صفحه | O2: ='14'!O2+1 -> 11
A3: خروجی بازنگری مدیریت | N3: مسئول | O3: تاریخ
A5: فرصت های برای بهبود | C5: ادامه اخذ گرید A | N5: مسولیت مدیریت/ کلیه فرایندها | O5: 1405
C6: درخواست تغییر در ساختار اتوماسیون به گونه ای که پاسخ های که منجر به اثر بخشی نباشد به صادر کننده عودت گردد ارزیابی اجرای سیستم مدیریت کیفیت به صورت مستمر و بررسی پیاده سازی سیستم مدیریت کیفیت در فرآیندها | N6: تضمین/IT | O6: 1405/12
C7: پایش مستمر شاخص های مشتری و صدور اقدام اصلاحی در صورت بروز افزایش ppm | N7: بازرسی / آزمون | O7: ماهیانه
A8: تغییرات مورد نیاز در سیستم مدیریت کیفیت | C8: تدوین برنامه مدونی با چشم انداز چند ساله برای تقویت و ارتقا پرسنل های چند مهارتی/ در صورت امکان job rotation | N8: منابع | O8: 1405/12
C9: انجام ممیزی مراقبتی اول برنامه ریزی شده است . | N9: مسولیت مدیریت/ کلیه فرایندها | O9: 1405
A19: شماره فرم : MA-F-19 | D19: شماره بروزرسانی : 0 | J19: تاریخ بروز رسانی : 99/05/10

Sheet 14
C1: فرم بازنگری مدیریت | N1: تاریخ | O1: ='1'!O1 -> 1405/05/22
N2: صفحه | O2: ='13'!O2+1 -> 10
A3: ورودی بازنگری مدیریت | C3: هدف | D3: معیار پذیرش | E3: شاخص دوره قبل | F3: شاخص این دوره | G3: تحلیل و بررسی | K3: اقدام پیشنهادی/منابع مورد نیاز | N3: مسئول | O3: تاریخ
A5: عملکرد ضمانت | C5: در حوزه خودروسازی سایپا و ایران خودرو ، هیچگونه شکایت و برگشتی در حوزه مصرف اعلام نشده است | N5: مهندسی/ کنترل کیفیت | O5: پیوسته
A7: بازنگری کارنامه مشتری 1401-1402 1401/07/01 1402/06/31 1403/06/31 1404/12/29 | C7: نتایج ارزیابی هفت معیار: | F7: صادرات | G7: ازداشبورد حذف شده است | H7: رقابت پذیری | J7: ازداشبورد حذف شده است | K7: ساخت | L7: ازداشبورد حذف شده است | M7: سرمایه گذاری | O7: ازداشبورد حذف شده است
C8: کیفیت | D8: 87.16 | E8: لجستیک | F8: 50 | G8: مهندسی | H8: ازداشبورد حذف شده است | K8: PPMکل | M8: 819 | N8: PPMسه ماهه | O8: 929
C9: بیشترین شماره فنی کلیم: | E9: X7V7041001AB | G9: 2244 | H9: IK00799080 | J9: 1746 | K9: YG20214191 | M9: 1211 | N9: YG22213511 | O9: 825
A10: گرید | B10: B + | C10: بیشترین شماره فنی تکرار کلیم: | G10: 160 | J10: 66 | M10: 217 | O10: 66
A11: اثر بخشی ممیزی ها | C11: متاسفانه اقدامات اصلاحی صادره ، به خوبی از سوی مالکان فرایندها تجزیه و تحلیل نمیگردد و صرفا اقداماتی جهت بسته شدن اقدام اصلاحی تعریف میگردد که منجر به بروز ایرادات تکراری چه در سطح سازمان و چه در نزد مشتری میگردد ، از آنجا که در ساختار اقدام اصلاحی موجود در سیستم اتوماسیون باکس اثربخش اقدام تعریف نشده است لذا بسته شدن اقدام معادل با اثربخش بودن تعریف میگردد قرار شد جهت افزایش اثر بخشی اقدامات اصلاحی از طرف مالکان فرایندها کلاس آموزشی استفاده از اتوماسیون جهت مالکان فرایندها برگزار گردد | K11: درخواست تغییر در ساختار اتوماسیون به گونه ای که پاسخ های که منجر به اثر بخشی نباشد به صادر کننده عودت گردد | N11: تضمین/ IT | O11: 1405/12
A14: خرابی های بالقوه عرصه مصرف شناسایی شده از طریق تحلیل ریسک | C14: خرابی های بالقوه عرصه مصرف در قالب PFMEA بررسی و ارزیابی میگردد و در صورت صدور شکایت از سوی مشتریان ضمن صدور 8D و تحلیل و ریشه یابی ، در صورت لزوم PFMEA به روز میگردد | N14: EN/QC | O14: پیوسته
A17: خرابی های بالفعل عرصه مصرف و تاثیر آنها بر ایمنی و محیط زیست | C17: در حوزه خرابی های بالفعل عرصه مصرف : بازدید از انبار داغی ها در دستور شرکت میباشد تا ضمن بررسی شاخص NTF ، موارد کیفی خرابی ها به واحدهای مرتبط ؛ به ویژه مهندسی انتقال خواهد یافت . | N17: اداری | O17: پیوسته
A21: شماره فرم : MA-F-19 | D21: شماره بروزرسانی : 0 | J21: تاریخ بروز رسانی : 99/05/10

Sheet 13
C1: فرم بازنگری مدیریت | N1: تاریخ | O1: ='1'!O1 -> 1405/05/22
N2: صفحه | O2: ='11-12'!O18+1 -> 9
A3: ورودی بازنگری مدیریت | C3: هدف | D3: معیار پذیرش | E3: شاخص دوره قبل | F3: شاخص این دوره | G3: تحلیل و بررسی | K3: اقدام پیشنهادی/منابع مورد نیاز | N3: مسئول | O3: تاریخ
A5: انطباق محصول | C5: نتایج بازرسی جامع ابعادی به پیوست ارائه میگردد
A9: ارزیابی های امکان سنجی ساخت | C9: در سال 1405 دو پروژه سینی زیر موتور آریا و سینی زیرموتورP 90 در حال پیگیری می باشد | N9: R&D ریرا در مهرماه در فاز تولید انبوه به صورت RAMP UP قرار گرفته است ساینا سال از اردیبهشت سال 1403 در فاز تولید انبوه قرار گرفته است . | O9: 1405/12
C11: جهت جبران حذف برخی از محصولات سازمان ، پروژه های سینی فن و سینی زیر موتور K125 و برخی از محصولات جدید گروه سایپا در جریان مذاکره با مشتری میباشد ، در صورت تایید بلافاصله فرایند تکوین آنها آغاز میگردد در سال 1403 امکان سنجی آریا و خودرو های سنگین صورت گرفته و در حال ساخت قالبها و تجهیزات است . ادامه روند مذکور در سال 1405 پروژه آریا به مراحل پایانی و تولید خواهد رسید.
A13: بازنگری عملکرد در مقابل اهداف نگهداری | B13: ربات | C13: روند کلی شاخصهای MTTR و MTBF روند خوبی است ولی با توجه به فرسایش تجهیزات پایدار نیست . در بعضی موارد افزایشی بوده و در پاره ای موارد روند بهبود دارد . جهت تغیر معیار پذیرش و حرکت جهت بهبود ملاک سالیانه مورد ارزیابی است. و در دوره بعد مورد بررسی قرار می گیرد.
B15: پرس
B17: کمپرسور
B19: اکسترودر
A21: شماره فرم : MA-F-19 | D21: شماره بروزرسانی : 0 | J21: تاریخ بروز رسانی : 99/05/10

Sheet 11-12
C1: فرم بازنگری مدیریت | N1: تاریخ | O1: ='1'!O1 -> 1405/05/22
N2: صفحه | O2: 7
A3: ورودی بازنگری مدیریت | C3: هدف | D3: معیار پذیرش | E3: شاخص دوره قبل | F3: شاخص این دوره | G3: تحلیل و بررسی | K3: اقدام پیشنهادی/منابع مورد نیاز | N3: مسئول | O3: تاریخ
A5: هزینه نقصان کیفیت | B5: درصد هزینه های پیشگیری نسبت به مجموع فروش یا هزینه های کیفی | E5: 0.23 | F5: 0.285 | G5: بیشترین هزینه در این بخش مربوط به هزینه های نگهداری و تعمیرات میباشد | K5: انجام تعمییرات پیش بینانه و پیش گیرانه جهت کنترل و کاهش هزینه های تعمییرات و نگهداری | N5: آموزش | O5: 1405/12
B9: درصد هزینه های ارزیابی نسبت به مجموع فروش یا هزینه های کیفی | E9: 0.23 | F9: 0.309 | G9: هزینه های ارزیابی در سه ماهه اول مربوط به تجمع ارزیابی های سازمان در این مدت می باشد . | N9: تضمین کیفیت | O9: 1405/12
B13: درصد هزینه های شکست داخلی نسبت به مجموع فروش یا هزینه های کیفی | E13: 0.35 | F13: 0.354
C17: فرم بازنگری مدیریت | N17: تاریخ | O17: ='1'!O1 -> 1405/05/22
N18: شماره | O18: 8
A19: ورودی بازنگری مدیریت | C19: هدف | D19: معیار پذیرش | E19: شاخص دوره قبل | F19: شاخص این دوره | G19: تحلیل و بررسی | K19: اقدام پیشنهادی/منابع مورد نیاز | N19: مسئول | O19: تاریخ
A21: هزینه نقصان کیفیت | B21: درصد هزینه های شکست خارجی نسبت به مجموع فروش یا هزینه های کیفی | E21: 0.08 | F21: 0.06 | G21: میزان کلیمها و اخطارهای کیفی دردوره محاسبه شده نسبت به دوره مشابه در سال قبل ؛ در سایت اصلی کم بوده و باعث کاهش میزان درصد هزینه شده است | K21: بهبود شرایط بسته بندی و ارسال قطعات به سایت های بیرون از تهران | N21: بازرگانی /فروش | O21: 1405/12
B25: درصد هزینه های کیفی | C25: 0.03 | D25: 0.025 | E25: 0.0258 | F25: 0.025 | G25: متوسط هزینه ماهیانه . کاهش میانگین ؛مربوط به عدم انجام ممیزی های سوم شخص به دلایل درگیری های نظامی در منطقه می باشد . | K25: شناسایی مواردی که باعث افزایش هزینه های شکست داخلی و خارجی و پیشگیری نسبت به فروش می گردد وتعریف اقدامات مناسب جهت رفع ریشه ای موارد عدم انطباق در کمیته C.F.T | N25: مدیریت ارشد کلیه فرآیندها | O25: 1405/12
A29: شماره فرم : MA-F-19 | D29: شماره بروزرسانی : 0 | J29: تاریخ بروز رسانی : 99/05/10

Sheet 10-
C1: فرم بازنگری مدیریت | N1: تاریخ | O1: ='1'!O1 -> 1405/05/22
N2: صفحه | O2: ='8-9'!O26+1 -> 10
A3: ورودی بازنگری مدیریت | C3: هدف | D3: معیار پذیرش | E3: شاخص دوره قبل | F3: شاخص این دوره | G3: تحلیل و بررسی | K3: اقدام پیشنهادی/منابع مورد نیاز | N3: مسئول | O3: تاریخ
A5: فرصت های برای بهبود | C5: 6 | D5: 4 | E5: 2 | F5: 7 | G5: ساخت فیکسچر خنک کاری جهت سینی زیر موتور ریرا ساخت رک خنک کاری جهت بیم تقویتی سینا سال | N5: مهندسی /نت | O5: انجام شده است
A7: شاخص های اثر بخشی فرایند | B7: از مهمترین شاخص های اثر بخشی که دارای انحراف قابل ملاحظه است
B8: درصد انحراف از پیش بینی فروش | C8: -0.1 | D8: -0.17 | E8: -0.135 | F8: -0.1038 | G8: با توجه به بررسی های صورت گرفته انحرافات مربوط به انحراف خودروساز از برنامه تدوین شده خودش میباشد | K8: پایش مستمر سفارش مشتری و به روز آوری پیش بینی فروش سازمان در صورت نیاز | N8: فروش | O8: پیوسته
B9: درصد اثر بخشی آموزش | C9: 0.8 | D9: 0.74 | E9: 83 | F9: 0.8567 | N9: آموزش | O9: پیوسته
B10: میانگین PPM داخلی پرس | C10: 4000 | D10: 8000 | E10: 4462 | F10: 3727 | G10: بیشترین ضایعات به محصولات LFT و قطعه 232با علل دفرمگی می باشد . | K10: با ساخت رک جهت خنک کاری قطعات اصلاح گردید . | N10: تولید | O10: پیوسته
B11: میانگین PPM داخلی ربات | C11: 93 | D11: 343 | E11: 201 | F11: 586 | G11: بیشترین ضایعات به محصولات SMC و قطعه X7با علل تریم نامناسب میباشد | K11: با تعویض کلمپ مشکل مرتفع گردید
B12: ساپکو PPM خارجی | C12: 600 | D12: 1000 | E12: 1577 | F12: 951.8 | G12: تحلیل و بررسی شاخص برگشت از مشتری در قالب پاراتو به پیوست می باشد . | K12: پایش مستمر شاخص های مشتری و صدور اقدام اصلاحی در صورت بروز افزایش ppm | N12: بازرسی و آزمون به همراه مهندسی و تولید | O12: ماهیانه
B13: سازه گستر PPM خارجی | C13: 600 | D13: 1000 | E13: 780 | F13: 703.9
A14: شاخص های کارایی فرایند | B14: از مهمترین شاخص های کارایی که دارای انحراف قابل ملاحظه است
B15: سرانه آموزش | C15: 3 | D15: 2.8 | E15: 3.05 | F15: 4
B16: سرانه پیشنهادات | C16: 6 | D16: 3 | E16: 4 | F16: 8.3
B17: میانگین تجهیزات MTTR | C17: 180 | D17: 250 | E17: 62 | F17: 70.5
B18: میانگین تجهیزات MTBF | C18: 250 | D18: 240 | E18: 365 | F18: 327.5
A19: شماره فرم : MA-F-19 | D19: شماره بروزرسانی : 0 | J19: تاریخ بروز رسانی : 99/05/10

Sheet 8-9
C1: فرم بازنگری مدیریت | N1: تاریخ | O1: ='1'!O1 -> 1405/05/22
N2: صفحه | O2: ='5-7'!O18+1 -> 8
A3: ورودی بازنگری مدیریت | C3: هدف | D3: معیار پذیرش | E3: شاخص دوره قبل | F3: شاخص این دوره | G3: تحلیل و بررسی | K3: اقدام پیشنهادی/منابع مورد نیاز | N3: مسئول | O3: تاریخ
A5: نتایج پایش و اندازه گیری | C5: MSA PLAN سال 1405 تدوین شده است | N5: QC | O5: 1405/12
C7: برنامه MSA سال1405 مطابق پلن تدوین شده جهت ابزارهای کنترلی فرایند تولید ( کولیس های 1 متر کنترلی کیفیت و 60 سانت آزمایشگاه ) انجام شده است
C9: R&R کولیس 1متری: | E9: 8.21
C11: CMK ماشین پانچ: | E11: 1.89 | F11: جهت سوراخ قطر 16 قطعه به شماره فنی YG22213511
C12: MSAوصفی نیز برای تمام پرسنل کنترل کیفیت انجام شده است
A13: کنترل آماری فرایند | C13: SPC PLAN سال 1405 تدوین شده است ) ( تاریخ تدوین بهمن 1404 )
C15: برنامه SPC سال 1405 مطابق پلن تدوین شده انجام شده است( تاریخ تدوین بهمن 1404 ) -جهت خانواده سینی زیر موتور شماره فنی YG22213511 و فاصله محل اتصال به خودرو انجام شده که نتایج آن بدین شرح میباشد:CP=2.45, CPK=1.68
A17: کفایت منابع | B17: انسانی | C17: کمبود اپراتور تولید | G17: بدلیل کمبود نیروی کار در منطقه ، میزان جذب کاهش یافته است | K17: تدوین برنامه مدونی با چشم انداز چند ساله برای تقویت و ارتقا پرسنل های چند مهارتی/ در صورت امکان job rotation | N17: منابع/آموزش | O17: 1405/12
B18: تجهیزاتی | C18: کمبود پالت یا کمبود فضای مسقف جهت انبارش قطعات | K18: ساخت 850 پالت ( بطور متوسط ماهیانه 50 پالت ) - ضمیمه شدن فضای شرکت ایمن ایستاالکتریک به فضای تولید و انبارش نیپکو . | N18: مدیریت/تدارکات | O18: 1405/12
B22: پایش و اندازه گیری | C22: کمبود نداریم
B23: فضا | C23: کمبود انبار نیم ساخته / انبار محصول سایت 1 | K23: با جابجایی شرکت ایمن ایستاالکتریک/ ساخت پالت /مشکل تا حد زیادی مرتفع میگردد | N23: بازرگانی /کارخانه | O23: 1405/12
C24: کمبود فضای انبار نیم ساخته جهت سالن 2 به میزان 700 مترمربع کمبود فضای انبار محصول سالن 2 به میزان | K24: ساخت سوله جهت انبار مواد اولیه/محصول در حال اجرا می باشد سوله سقف دارد ولی دیوار ندارد . | N24: مدیریت سالن 2
C25: فرم بازنگری مدیریت | N25: تاریخ | O25: ='1'!O1 -> 1405/05/22
N26: صفحه | O26: =O2+1 -> 9
A27: ورودی بازنگری مدیریت | C27: هدف | D27: معیار پذیرش | E27: شاخص دوره قبل | F27: شاخص این دوره | G27: تحلیل و بررسی | K27: اقدام پیشنهادی/منابع مورد نیاز | N27: مسئول | O27: تاریخ
A29: اثر بخشی اقدامات انجام شده در پرداختن به ریسک و فرصت ها | C29: مهمترین ریسک در شرایط کنونی: تحریم /عدم ثبات و امنیت در منطقه /بالا بودن ریسک عدم تامین مواد اولیه و ملزومات از خارج از کشور /کمبود نقدینگی/ عدم پرداخت به موقع مطالبات توسط مشتری/ حذف برخی خودروها و در نتیجه حذف برخی از محصولات | K29: واگذاری فروش آزاد به نورایستا خراسان و افزایش میزان فروش بازار | N29: بازگانی نورایستا خراسان | O29: بطور مستمر
K30: اخذ محصولات جدید مربوط به خودروهای جدید و خودروهای تجاری پروژه در دست انجام قطعات مایان می باشد | N30: تحقیق و توسعه کلیه فرآیندها | O30: بطور مستمر
K31: پایش فرآیندهای بورس | N31: مالی | O31: 1405/08
K32: انجام الزامات IMS جهت گرید A ساپکو | N32: کلیه فرایندها/QE | O32: 1406/02
A33: شماره فرم : MA-F-19 | D33: شماره بروزرسانی : 0 | J33: تاریخ بروز رسانی : 99/05/10

Sheet 5-7 (2)
C1: فرم بازنگری مدیریت | N1: تاریخ | O1: ='1'!O1 -> 1405/05/22
N2: صفحه | O2: ='[1]2-4'!O39+1 -> 5
A3: ورودی بازنگری مدیریت | C3: هدف | D3: معیار پذیرش | E3: شاخص دوره قبل | F3: شاخص این دوره | G3: تحلیل و بررسی | K3: اقدام پیشنهادی/منابع مورد نیاز | N3: مسئول | O3: تاریخ
A5: ممیزی داخلی | B5: مدیریت کیفیت | C5: 1-بروز رسانی مدارک (7-5-1-1)بر اساس الزامات جدید خودرو سازی صورت گیرد. ISSR_V2 مدارک در خصوص FR و سیستم تشدید نیاز به بازنگری دارد. الزامات مشتری 2-اثربخشی اقدامات اصلاحی ناقص انجام می شود.10-2-1 3-با توجه به عملکرد یکساله و بهبود بعضی از شاخصها در حوزه نت نیاز به تعریف مجدد از اهداف شاخص می باشد. تجزیه و تحلیل در این زمینه مشاهده نشد.9-3-2 | G5: عدم اجرای بند استاندارد توسط مسئولین فرآیند | K5: شناسنامه فرآیندها براساس SIPOC تدوین گردد و شاخص ها بروز رسانی گردد . | N5: QA | O5: 1405/12
B6: منابع انسانی | C6: 1-شرایط ماتریس مهارت مطلوب نیست 7-2-1. 2-اپراتورهایی که در سالن جدید هستند قابل شناسایی نیستند. الزام مشتری 3-انگیزش کارکنان و نظر سنجی اثربخشی اقدامات انگیزشی مشاهده نشد.7-3-2 | N6: H.R | O6: 1405/12
B7: خرید داخلی | C7: 1-اخذ PPAP و ارزیابی نور ایستا خراسان صورت نگرفته است.(8-3 ) 2-مدارک ارزیابی مشاهده نشد.(8-4-2-4-1)- 1-انطباق قانونی و مقرراتی در کنترل اقلام ورودی مشاهده نشد .8-6-5 | G7: عدم پیگیری تدارکات داخلی از تامین کنندگان | K7: پیگیری از تامین کنندگان | N7: تدارکات داخلی | O7: 1405/12
B8: خرید خارجی | C8: زمان دموراژ با توجه به ثابت بودن و تحت کنترل نبودن لحاظ نشده. و زمانهای مرتبط به واردات کالا تحت کنترل نیست و خصوصا زمان اختصاص ارز که مرتبط با سیاستهای دولت می باشد. | G8: عدم اجرای بند استاندارد توسط مسئولین فرآیند | K8: شناسنامه فرآیندها براساس SIPOC تدوین گردد و شاخص ها بروز رسانی گردد . | N8: مسئولیت مدیریت / کلیه فرآیندها | O8: 1405/12
B9: تولید | C9: 1-ردیابی قطعات از بعد از پرس انجام نمی شود8-5-2-1.2- 5S سالن تولید نیازمند برنامه ریزی است شرایط مطلوبی ندارد. 3-انبارش کالای نیمه ساخته با توجه به بروز نبودن تحت کنترل نیست .
B10: مهندسی | C10: 1-فرایندهای جایگزین (8-5-6-1-1)مشخصات مهندسی برای همه ایستگاه پرسکاری و کد قالبها صورت نگرفته. 2-بررسی الزامات قانونی در خصوص تامین کنندگان در داده های خرید مشاهده نشد. 8-4-2-2
B11: برنامه ریزی | C11: 8-5-1-7- پایش زمان انتظار صورت نمی گیرد . و ازجمله الزامات لجستیک ساپکو بصورت جامع اجرا نشده است.
C12: فرم بازنگری مدیریت | N12: تاریخ | O12: ='1'!O1 -> 1405/05/22
N13: صفحه | O13: =O2+1 -> 6
A14: ورودی بازنگری مدیریت | C14: هدف | D14: معیار پذیرش | E14: شاخص دوره قبل | F14: شاخص این دوره | G14: تحلیل و بررسی | K14: اقدام پیشنهادی/منابع مورد نیاز | N14: مسئول | O14: تاریخ
A16: ممیزی داخلی | B16: نت | C16: - | G16: ....... | K16: ....... | N16: ....... | O16: .......
B17: بازرسی و آزمون | C17: 1-اولین قطعه بعد از راه اندازی و اخرین قطعه قبل از توقف تولید مشاهده نشد.8-5-1-3 | G17: عدم وجود برچسب جهت تایید قطعه اول | K17: برچسب جهت تایید قطعه اول شیفت تهیه شده است | N17: کنترل کیفیت | O17: 1405/08
B18: تحقیق توسعه | C18: 1-مدارک امکانسنجی محصول آریا ناقص است. مدارک DFMEA و قیمت تمام شده مشاهده نشد. کنترل پروژه بر اساس تاریخ است . شرح کار مشاهده نشد. | G18: عدم تسلط کارشناس تکوین محصول در فرآیند تحقیق و توسعه | K18: پایش فرآیند تحقیق و توسعه | N18: تضمین کیفیت | O18: 1405/12
B19: فروش و بازنگری قرارداد | C19: بندهای لجستیک ساپکو بصورت جامع اجرا نشده است. | G19: عدم تسلط فرآیندهای سازمان به الزامات لجستیک | K19: آموزش فرآیندهای مرتبط با لجستیک | N19: مسئولیت مدیریت / کلیه فرآیندها | O19: 1405/12
B20: انبارش | C20: 1-چک لیست دریافت مواد اولیه مشاهده نشد. | G20: عدم تسلط فرآیندهای سازمان به الزامات لجستیک | K20: آموزش فرآیندهای مرتبط با لجستیک | N20: مسئولیت مدیریت / کلیه فرآیندها | O20: 1405/12
B21: مسئولیت مدیریت | C21: 1-مسئولیت عدم ارسال محصول نامنطبق بخوبی صورت نمی گیرد. مسئولین تولید با الزامات تائید قطعه آشنا نمی باشند. 5-3-2 2-مسئولیت نگهداری و تعمیرات دارای صلاحیت و شایستگی کافی نمی باشد. 7-2-1 3-نگهداری بهره ور جامع بخوبی صورت نمی گیرد 8-5-1-5 | G21: سایت جنوبی | K21: تغییر عمده در سیستم مدیریت سالن جنوبی - تیم مستقر در سالن جنوبی فاقد آگاهی ؛ صلاحیت نسبت به پیاده سازی استاندارد می باشند . | N21: مسئولیت مدیریت / کلیه فرآیندها | O21: 1405/12
B22: کلیه فرایندها | C22: ریسک حملات سایبری 6-1-2-3 | G22: عدم اجرای کامل حفاظت شبکه | K22: اجرای حفاظت شبکه | N22: مسئولیت مدیریت / کلیه فرآیندها | O22: 1405/12
A23: شماره فرم : MA-F-19 | D23: شماره بروزرسانی : 0 | J23: تاریخ بروز رسانی : 99/05/10

Sheet 5-7
C1: فرم بازنگری مدیریت | N1: تاریخ | O1: ='1'!O1 -> 1405/05/22
N2: صفحه | O2: ='2-4'!O38+1 -> 5
A3: ورودی بازنگری مدیریت | C3: هدف | D3: معیار پذیرش | E3: شاخص دوره قبل | F3: شاخص این دوره | G3: تحلیل و بررسی | K3: اقدام پیشنهادی/منابع مورد نیاز | N3: مسئول | O3: تاریخ
A5: ممیزی داخلی | B5: توليد | C5: 1- بند 7-1-4 ( محیط عملیات فرایندها ) : 5S در خط تولید به طور مناسبی رعایت نمی شود . 2- بند 7-1-3 ( زیر ساخت ) FIFO در خط تولید به درستی رعایت نمی شود . 4- بند 8-7-1 ( کنترل محصول مشکوک ) : فضای مجزای برای اقلام مشکوک در تولید وجود ندارد | G5: بدلیل کمبود فضا و نبود انبار نیم ساخته مشکلات فوق ، ایجاد شده است | K5: با ساخت پالت های برنامه ریزی شده و فضای حاصل از جابجایی سایت نورایستا خراسان ، مشکل تا حدود زیادی مرتفع میشود | N5: مدیریت عامل/ بازرگانی | O5: 1405/12
B6: منابع انسانی | C6: بند 6-1-1 ( رسیدگی به ریسک ها و فرصت ها ) ارزیابی ریسک فرایند منابع انسانی بروز نمی باشد . 2- بند 5-1-1 ( مسئولیت سازمان ) سیاستهای مسئولیت سازمانی از جمله سیاستهای ضد ارتشاء . کدهای رفتاری کارکنان و سیاست اخلاقی افشاگری در سازمان اثربخش نمی باشد . 3- بند 7-3 ( آگاهی پرسنل ) عدم وجود ساز و کار مناسبی جهت آگاهی پرسنل از پیامدهای عدم انطباق با نیازمندیها مشتریان و سازمان 4- بند 7-1-6 ( دانش سازمانی ) طرحریزی و اجرای دانش سازمانی در سازمان اثربخش نمی باشد . 5- بند 7-1 ( منابع ) برنامه ریزی تقویم آموزشی اثربخش نمی باشد . 6- بند 5-3 ( نقش ها ، مسئولیت ها و اختیارات سازمانی ) شناسنامه شغل پرسنل نیازمند بروزرسانی می باشد از قبیل سرپرست کنترل کیفیت 7- الزام مشتری STAS : ماتریس مهارت و سطوح احراز صلاحیت پرسنل تولید در ایستگاههای کاری مشاهده نشد . 8- بند 7-1-3-1 ( طرحریزی کارخانه ، تسهیلات و تجهیزات ) تیم های چند تخصصی برای شناسایی ریسک ها ، توسعه و بهبود عملکرد فرایندهای سازمان وجود ندارد . | G6: عدم تکمیل نیاز سنجی آموزشی | K6: تکمیل نیاز سنجی | N6: منابع | O6: 1405/012
B7: خرید داخلی | C7: عدم به روز بودن طرح اقتضایی/ ناقص بودن فرم ریسک تامین کنندگان/ ناقص بودن تست ریپورت های در یافتی/ اثر بخش نبودن اقدامات توسعه تامین کنندگان/عدم وجود پایش عملکرد (شرکت های پایا پلاست و پلیمر تدبیر نیکان)/ناقص بودن فرم استاندارد سفارش گذاری ( نبودن شیلد حرارتی و ورق smc) | G7: عدم تکمیل نیاز سنجی آموزشی | K7: تکمیل نیاز سنجی
B8: خرید خارجی | C8: عدم به روز بودن ریسک ها و طرح های اقتضایی عدم تکمیل فرم استاندارد سفارش گذاری و حمل | G8: عدم تکمیل نیاز سنجی آموزشی | K8: تکمیل نیاز سنجی
C9: فرم بازنگری مدیریت | N9: تاریخ | O9: ='1'!O1 -> 1405/05/22
N10: صفحه | O10: =O2+1 -> 6
A11: ورودی بازنگری مدیریت | C11: هدف | D11: معیار پذیرش | E11: شاخص دوره قبل | F11: شاخص این دوره | G11: تحلیل و بررسی | K11: اقدام پیشنهادی/منابع مورد نیاز | N11: مسئول | O11: تاریخ
A13: ممیزی داخلی | B13: بازرسي و آزمون | C13: 1- آدیت لایه ای 2 و 3 انجام نمی شود . 2- عدم دسترسی به قطعات مرجع 3- روش استارت آپ استاندارد و کامل نمی باشد(صدور مجوزهای راه اندازی و تصدیق فرآیند - موثر نمی باشد) 4- ردیابی و شناسایی قطعات دوباره کاری انجام نمی شود . 5- وجود قطعات مشکوک در انبار و خط تولید | G13: عدم تکمیل نیاز سنجی آموزشی | K13: تکمیل نیاز سنجی | N13: منابع | O13: 1405/12
B14: فروش و بازنگری قرارداد | C14: براساس ممیزی لجستیک ساپکو موارد اقدام اصلاحی به صورت گانت چارت لجستیک در حال پیگیری و اجرا می باشد | N14: کمیته لجستیک | O14: 1405/12
B15: نگهداری و تعمیرات | C15: 1- بند 8-5-1-5 ( نگهداری بهره ور جامع ) لیست ماشین آلات نیازمند بروزرسانی می باشد به طور مثال عدم ثبت دستگاه یونیت سوراخکاری و برنامه نگهداری پیشیگرانه در لیست ماشین آلات . 2- بند 6-2-1 ( اهداف کیفیت ) نحوه محاسبه شاخص های عملکردی به درستی انجام نشده است . به عنوان مثال مقدار MTTR برای پرس 1200 تن برای اردیبهشت ماه صحیح محاسبه نشده است | G15: عدم تکمیل نیاز سنجی آموزشی | K15: تکمیل نیاز سنجی | N15: منابع | O15: 1405/12
B16: برنامه ریزی | C16: 1- افراد شاغل در انبار موارد اولیه فاقد آموزشهای ایمنی می باشند . 2- مکانی مناسب جهت انجام عملیات بارانداز موجود نمی باشد . 3- عدم دریافت موجودی واقعی با موجودی سیستم به علت بسته بودن سیستم توسط واحد مالی . 4- در انبار مواد اولیه از آنالیز ABC ارزشی جهت سهولت در شناسایی اقلام تند مصرف و کند مصرف و راکد استفاده نمی شود . 5- روشی نظامند در سیستم آدرس دهی در قفسه ها در انبار موجود نمی باشد . 6- از سیستم مدیریت دیداری در انبار موارد اولیه استفاده نمی شود . ( حداکثر و حداقل سطوح موجودی ) 7- ازریابی دوره ای انبار انجام نمی شود . 8- بند 7-5-2 ( ایجاد و بروزرسانی ) روش اجرایی شناسایی و ردیابی محصولات بروز نمی باشد . | G16: عدم تکمیل نیاز سنجی آموزشی | K16: تکمیل نیاز سنجی
C17: فرم بازنگری مدیریت | N17: تاریخ | O17: ='1'!O1 -> 1405/05/22
N18: صفحه | O18: =O10+1 -> 7
A19: ورودی بازنگری مدیریت | C19: هدف | D19: معیار پذیرش | E19: شاخص دوره قبل | F19: شاخص این دوره | G19: تحلیل و بررسی | K19: اقدام پیشنهادی/منابع مورد نیاز | N19: مسئول | O19: تاریخ
A21: ممیزی داخلی | B21: امور مهندسی | C21: 2- بند 7-3-5 ( کنترل اطلاعات مدون ) ساز و کار مناسبی جهت حفظ ، نگهداری و Back up گیری از برنامه های تجهیزات وجود ندارد از قبیل ربات ها 3- بند 7-1-3-1 ( طرحریزی کارخانه . تسهیلات و تجهیزات ) Layout سالن تولید بروز نمی باشد . به عنوان مثال جایگاه دستگاه یونیت سوراخکاری در لی اوت قابل مشاهده نمی باشد . 4- بند 7-5-2 ( ایجاد و بروزرسانی ) مستندات فنی از قبیل مستر لیست مدارک فنی بروز نمی باشد . 5- بند 8-5-6-1 ( کنترل تغییرات ) فرایند تغییرات مهندسی اثر بخش نمی باشد به عنوان مثال تغییرات انجام شده در فرایند سوراخکاری محصولات سینی فن در مدارک فنی لحاظ نشده است . 6- بند 6-3 ( طرح ریزی تغییرات ) فرایند طرح ریزی تغییرات اثر بخش نمی باشد به عنوان مثال پیامدهای بالقوه ناشی از تغییرات به درستی ارزیابی نشده است . 7- بند 8-3-5-2 ( خروجی طراحی فرایند ساخت ) وجود مغایرت در اهمیت پارامترهای مهم محصول و فرایند به طور مثال درصد الیاف در جزو مشخصات مهم محصول با اهمیت A می باشد ولی در پارامترهای مهم فرایند با اهمیت B لحاظ شده است . 8- بند 8-3-5-2 ( خروجی طراحی فرایند ساخت ) عدم عنوان یکی از OP ها در FPC به عنوان مثال نصب فرم در قطعه 231 در FPC و برنامه کنترل مشاهده نشده است . 9- بند 8-6-2( بازرسی جامع ابعادی و آزمون عملکردی ) داده ها و اطلاعات مربوط به بازرسی جامع ابعادی و آزمون عملکردی بروز نمی باشد . 10- بند 9-1-1-2 ( شناسایی ابزارهای آماری ) استفاده از ابزارهای آماری در تحلیل ها اثر بخش نمی باشد . 11- 10-2-1 (عدم انطباق و اقدام اصلاحی ) ریشه یابی اقدامات اصلاحی اثر بخش نمی باشد . به عنوان مثال اقدام اصلاحی به شماره SALE/01/163 به درستی ریشه یابی نشده است . 12- بند 10-2-3 ( حل مسئله ) استفاده از تکنیک حل مسئله در تحلیل مشکلات کیفی اثر بخش نمی باشد . به عنوان مثال در اخطار کیفی سختی مونتاژ ( جا نرفتن ) از روش حل مسئله استفاده نشده است . عدم وجود داده های خرید خارجی / عدم وجود داده خرید شیلد حرارتی | G21: عدم تکمیل نیاز سنجی آموزشی | K21: تکمیل نیاز سنجی | N21: منابع | O21: 1405/012
A22: شماره فرم : MA-F-19 | D22: شماره بروزرسانی : 0 | J22: تاریخ بروز رسانی : 99/05/10

Sheet 2-4
C1: بازنگری مدیریت | N1: تاریخ | O1: ='1'!O1 -> 1405/05/22
N2: صفحه | O2: ='1'!O2+1 -> 2
A3: ورودی بازنگری مدیریت | C3: هدف | D3: معیار پذیرش | E3: شاخص دوره قبل | F3: شاخص این دوره | G3: تحلیل و بررسی | K3: اقدام پیشنهادی/منابع مورد نیاز | N3: مسئول | O3: تاریخ
A5: عملکرد فرایند و انطباق محصولات و خدمات | B5: درصد امتیاز عملکرد تامین کنندگان داخلی | C5: 100 | D5: 70 | E5: 100 | F5: 100 | N5: تدارکات داخلی | O5: سه ماهه | Q5: کارا
B6: درصد انحراف از پیش بینی فروش | C6: -0.1 | D6: -0.17 | E6: -0.11 | F6: -0.1038 | N6: فروش | O6: پیوسته | Q6: اث
B7: درصد اثر بخشی آموزش | C7: 0.8 | D7: 0.74 | E7: 0.875 | F7: 0.95 | N7: منابع/ آموزش | O7: شش ماهه | Q7: اث
B8: سرانه آموزش | C8: 3 | D8: 2.8 | E8: 5.99 | F8: 4 | G8: به دلیل شرایط جنگی حاکم بر کشور و تعدیل شیفت نسبت بدوره قبل کاهش داشته است . | Q8: کارا
B9: درصد تحقق برنامه آموزشی | C9: 80 | D9: 74 | E9: 0.88 | F9: 0.93 | Q9: اث
B10: سرانه پیشنهادات | C10: 6 | D10: 3 | E10: 4.5 | F10: 9 | Q10: کارا
B11: درصد رضایت پرسنل | C11: 85 | D11: 70 | E11: 74 | F11: 76 | G11: افزایش حقوق ها در ابتدای سال شرایط را بهتر کرده است - لیکن با توجه به وضعیت معیشتی و تورم رضایت پرسنل کامل نمی باشد . | O11: سالیانه | Q11: اث
B12: میانگین فراوانی حادثه | C12: 0 | D12: 20 | E12: 4.97 | F12: 2 | N12: ایمنی | O12: پیوسته | Q12: اث
B13: میانگین شدت حادثه | C13: 0 | D13: 1 | E13: 0.22 | F13: 0.1 | Q13: کارا
B14: درصد اقدامات اصلاحی اثر بخش | C14: 65 | D14: 60 | E14: 73.69 | F14: 75 | N14: تیم CFT | Q14: اث
B15: درصد هزینه های کیفیت به فروش | C15: 3 | D15: 2.5 | E15: 2.3 | F15: 2.5 | N15: مالی/ تضمین | O15: سه ماهه | Q15: اث
B16: تعداد پروژ های اخذ شده | C16: 3 | D16: 1 | E16: 1 | F16: 2 | G16: تعداد پروژه های خودرو سبک 1 آریا و سنگین 2 مایان و ایران خودرو دیزل | N16: تحقیق و توسعه | O16: سالیانه | Q16: کارا
B17: امتیاز ارزیابی انبار | C17: 1 | D17: 0.85 | E17: 0.97 | F17: 0.9825 | N17: کیفیت | O17: 3سه ماهه | Q17: اث
B18: میانگین تعداد قطعه به نفر ربات و پرس | C18: 2100 | D18: 1800 | E18: 1004.63 | F18: 1610 | G18: جذب نیروهای جدید و عدم دسترسی کامل به راندمان مناسب در تولید | N18: تولید | O18: ماهیانه
B19: میانگین PPM ضایعات پرس | C19: 4000 | D19: 8000 | E19: 6959 | F19: 3727 | N19: تولید/ مهندسی | O19: ماهیانه | Q19: اث
B20: میانگین PPM ضایعات ربات | C20: 400 | D20: 650 | E20: 203.82 | F20: 586.59 | Q20: اث
A21: شماره فرم : MA-F-19 | D21: شماره بروزرسانی : 0 | J21: تاریخ بروز رسانی : 99/05/10
C22: بازنگری مدیریت | N22: تاریخ | O22: ='1'!O1 -> 1405/05/22
N23: صفحه | O23: =O2+1 -> 3
A24: ورودی بازنگری مدیریت | C24: هدف | D24: معیار پذیرش | E24: شاخص دوره قبل | F24: شاخص این دوره | G24: تحلیل و بررسی | K24: اقدام پیشنهادی/منابع مورد نیاز | N24: مسئول | O24: تاریخ
A26: عملکرد فرایند و انطباق محصولات و خدمات | B26: درصد تحقق برنامه تولید | C26: 92 | D26: 85 | E26: 82.29 | F26: 87.68 | G26: کمبود نیروی انسانی | N26: برنامه ریزی | O26: ماهیانه
B27: میانگین درصد توقفات تولید | C27: 0 | D27: 5 | E27: 9.88 | F27: 7.21 | G27: مربوط به کمبود نیروی انسانی می باشد. | Q27: ک
B28: PPMکل ساپکو | C28: 600 | D28: 1000 | E28: 1577 | F28: 951.83 | G28: تحلیل و بررسی براساس روش پاراتور به پیوست می باشد . | K28: سینی فن 206 سینی زیر موتور EF7 وسینی جاچراغی سمند | N28: بازرسی/ آزمون | O28: ماهیانه | Q28: ا
B29: PPM کل خدمات پس از فروش ساپکو | C29: 0 | D29: 20 | E29: 0 | F29: 0 | Q29: ک
B30: امتیاز سنجش عملکرد ساپکو | C30: 100 | D30: 70 | E30: 85.26 | F30: 90.87 | G30: عدم اجرای جامع الزامات لجستیکی بالا بودن شاخص PPM سازمان در حوزه ساپکو | Q30: ا
B31: PPMکل سازه گستر | C31: 600 | D31: 1000 | E31: 547 | F31: 703.92 | Q31: ک
B32: PPM کل خدمات پس از فروش سازه گستر | C32: 0 | D32: 20 | E32: 0 | F32: 0 | Q32: ک
B33: امتیاز سنجش عملکرد سازه گستر | C33: 100 | D33: 70 | E33: 93 | F33: 98.13 | Q33: ا
B34: رضایت مشتریان(امتیاز) | C34: 85 | D34: 75 | E34: 93.75 | F34: 96.58 | N34: فروش (رضایت مشتری) | O34: سالیانه
B35: OTD | C35: 100 | D35: 80 | E35: 93.75 | F35: 96.47 | O35: ماهیانه
B36: میانگین تجهیزات MTTR | C36: 180 | D36: 215 | E36: 98.99 | F36: 74.86 | N36: تعمیرات و نگهداری | O36: ماهیانه
C37: بازنگری مدیریت | N37: تاریخ | O37: ='1'!O1 -> 1405/05/22
N38: صفحه | O38: =O23+1 -> 4
A39: ورودی بازنگری مدیریت | C39: هدف | D39: معیار پذیرش | E39: شاخص دوره قبل | F39: شاخص این دوره | G39: تحلیل و بررسی | K39: اقدام پیشنهادی/منابع مورد نیاز | N39: مسئول | O39: تاریخ
A41: عملکرد فرایند و انطباق محصولات و خدمات | B41: میانگین تجهیزات MTBF | C41: 250 | D41: 240 | E41: 348.31 | F41: 325
B42: میانگین قالب/ربات MTTR | C42: 62 | D42: 90 | E42: 98.99 | F42: 40 | N42: مهندسی | O42: ماهیانه
B43: میانگین قالب/ربات MTBF | C43: 135 | D43: 105 | E43: 282.59 | F43: 174.5
...

Sheet 1 (2)
C1: فرم بازنگری مدیریت درحوزه I.M.S | N1: تاریخ | O1: ='1'!O1 -> 1405/05/22
N2: صفحه | O2: 1
A3: ورودی بازنگری مدیریت | C3: هدف | D3: معیار پذیرش | E3: شاخص دوره قبل | F3: شاخص این دوره | G3: تحلیل و بررسی | K3: اقدام پیشنهادی/منابع مورد نیاز | N3: مسئول | O3: تاریخ
A4: وضعیت اقدامات بازنگری مدیریت قبلی | B4: فرصتهای بهبود : | C4: با توجه به نامه از طرف گروه ارزیابی ساپکو برای ISSR-V2 سازمان جهت گواهینامه IMS اقدام کرده است. | G4: اخذ گواهینامه انجام شده است - ممیزی مراقبتب اول برنامه ریزی شده است . | K4: تدوین مستندات جدید در راستای IMS | N4: ادارای /کلیه فرآیندها | O4: 1405/09
C5: ارتقاء سیستم 5S در سازمان جهت بهبود شرایط ایمنی و بهداشت و حفظ محیط زیست | G5: تدوین مستندات 5S و جاری سازی آن در سازمان براساس گانت تهیه شده در حال انجام است . | N5: کلیه فرایندها
B6: نیازمندیهای منابع: | C6: اقدامات لجستیکی ساپکو با توجه به محدودیت فضا . نیاز به نیرو در واحد تضمین در راستای استاندارد جدید و آموزش جهت موارد IMS برای ممیزی داخلی | G6: مقر گردید طی شش ماهه دوم 1405 یا تا پایان آذر1405 فضای سوله ایمن ایستاالکتریک که در شرق شرکت می باشد به فضای نورایستاپلاستیک اضافه شود.
B7: تغییرات در سیستم مدیریت کیفیت: | C7: افزایش اسکوپ استاندارد و اخذ گواهینامه جدید | G7: اخذ گواهینامه انجام شده است - ممیزی مراقبتب اول برنامه ریزی شده است . | K7: تدوین مستندات جدید در راستای IMS | N7: ادارای /کلیه فرآیندها
A8: تغییر در مسایل داخلی و خارجی سیستم مدیریت کیفیت در حوزه استاندارد I.M.S | B8: مسایل داخلی | C8: حوزه مرتبط با محاسبه و اعلام هزینه های لجستیکی | K8: تدوین مستندات جدید در راستای IMS | N8: مالی /کلیه فرآیندها
C9: ساخت پالت جهت افزایش انعطاف لجستیکی سازمان | K9: تعداد 50 عدد از هر پالت ساخته شده است و بنابراعلام تغييرات در برنامه ايرانخودرو متوقف گرديد
C10: راه اندازی جرثقیل سقفی در سایت اصلی نیپکو جهت افزایش انعطاف سازمان در کاهعش زمان انتظار تعویض قالب | K10: انجام شده است
C11: خرید و نصب و راه اندازی یک دستگاه پرس 500 تن در سایت دوم | K11: انجام شده است
C12: کمبود فضاری انبارش در تولید و انبار محصول به میزان 623 متر مربع می باشد . | K12: انتقال شرکت ایمن ایستالکتریک از همسایگی سایت های یک و دو نیپکو و افزایش فضای شرکت ایمن ایستا جهت رفع کمبود فضای انبارش | N12: مدیریت سازمان /مدیرعامل ایمن ایستا /مدیران سایتهای نیپکو | O12: 1405/12
B16: مسایل خارجی | C16: با توجه به ادامه تحریم ها و مشکلات موجود در صنعت به ویژه صنعت خودرو ، هنوز مشکل عدم تامین نقدینگی مشتریان وجود دارد | K16: توجه به فروش After Market | N16: شرکت نورایستا خراسان | O16: پیوسته
K17: از طریق جذب محصولات جدید | N17: تحقیق و توسعه/فروش | O17: پیوسته
K18: از طریق اخذ گرید A | N18: CFT/MD | O18: 1405
C19: حذف برخی از خودروها(پارس-تیبا-ساینا) از چرخه تولید و نتیجتا حذف برخی از محصولات تولیدی شرکت | K19: افزایش پروژه ها و جایگزینی محصولات حذف شده | N19: تحقیق و توسعه/فروش | O19: پیوسته
C20: ورود به بازار بورس | K20: انجام شده است | N20: مالی | O20: 1405/04
A21: رضایت مشتری خارجی | B21: ساپکو | N21: فروش | O21: 1405/06
B22: سازه گستر
A23: رضایت ذینفعان | B23: سهامداران سهامی عام /بورس | C23: با توجه به تعهدات سال 1404 سازمان به سهامداران و برگزاری مجمع ، تعهدات تعیین شده محقق شده است. | N23: مدیریت | O23: پیوسته
B24: کارکنان | C24: به هر یک از پرسنل شرکت تعداد 300 سهم بصورت پاداش واگذار شد. | N24: مدیریت
B25: جامعه عام | C25: چرخه محیط زیست محصول با استاندارد ISO 140001 ، مسئولیت اجتماعی در راستای اشتغالزایی و ارائه سهام برای خرید عموم | N25: تضمین کیفیت/مهندسی
B26: جامعه خاص | C26: در حوزه اداره کار، بیمه ، مالیات ، شهرداری ، شهرکهای صنعتی و محیط زیست مشکلی وجود نداشته است | N26: منابع
A27: میزان برآورده شدن دستیابی به اهداف کلان درحوزه I.M.S | C27: 100 | D27: 70 | E27: 91.02 | F27: 76.23 | G27: کاهش امتیاز O.T.D در تحویل قطعات ایساکو | N27: مدیریت
A28: شماره فرم : MA-F-19 | D28: شماره بروزرسانی : 0 | J28: تاریخ بروز رسانی : 99/05/10

Sheet 1
C1: فرم بازنگری مدیریت در حوزه I.A.T.F | N1: تاریخ | O1: 1405/05/22
N2: صفحه | O2: 1
A3: ورودی بازنگری مدیریت | C3: هدف | D3: معیار پذیرش | E3: شاخص دوره قبل | F3: شاخص این دوره | G3: تحلیل و بررسی | K3: اقدام پیشنهادی/منابع مورد نیاز | N3: مسئول | O3: تاریخ
A4: وضعیت اقدامات بازنگری مدیریت قبلی | B4: فرصتهای بهبود : | C4: با توجه به نامه از طرف گروه ارزیابی ساپکو برای ISSR-V2 سازمان جهت گواهینامه IMS اقدام کرده است. | G4: انعقاد قرارداد جهت اخذ گواهینامه IMS IPRO-03-14393-A به تاریخ 1403/05/10 | K4: تدوین مستندات جدید در راستای IMS | N4: ادارای /کلیه فرآیندها | O4: 1405/09
C5: اخذ گرید A ساپکو مطابق با برنامه در حال اجرا میباشد | G5: در سال 1401 دو ممیزی در حوزه کیفیت توسط مشتری انجام شده و گرید B پلاس تثبیت شد. مقرر گردید ممیزی لجستیک در تاریخ 1402/06/12 انجام گرددیده است | K5: تدوین مستندات لجستیک و جاری سازی آن در سازمان براساس گانت تهیه شده در حال انجام است . | N5: کلیه فرایندها
B6: نیازمندیهای منابع: | C6: اقدامات لجستیکی ساپکو با توجه به محدودیت فضا . نیاز به نیرو در واحد تضمین در راستای استاندارد جدید و آموزش جهت موارد IMS برای ممیزی داخلی | G6: مقر گردید طی شش ماهه دوم 1405 یا تا پایان شهریور 1406 فضای سوله ایمن ایستاالکتریک که در شرق شرکت می باشد به فضای نورایستاپلاستیک اضافه شود.
B7: تغییرات در سیستم مدیریت کیفیت:
A8: تغییر در مسایل داخلی و خارجی سیستم مدیریت کیفیت | B8: مسایل داخلی | C8: حوزه مرتبط با محاسبه و اعلام هزینه های لجستیکی | K8: تدوین مستندات جدید در راستای IMS | N8: مالی /کلیه فرآیندها
C9: ساخت پالت جهت افزایش انعطاف لجستیکی سازمان | K9: تعداد 50 عدد از هر پالت ساخته شده است و بنابراعلام تغييرات در برنامه ايرانخودرو متوقف گرديد
C10: راه اندازی جرثقیل سقفی در سایت اصلی نیپکو جهت افزایش انعطاف سازمان در کاهش زمان انتظار تعویض قالب | K10: انجام شده است
C11: خرید و نصب و راه اندازی یک دستگاه پرس 500 تن در سایت دوم | K11: انجام شده است
C12: کمبود فضاری انبارش در تولید و انبار محصول به میزان 623 متر مربع می باشد . | K12: انتقال شرکت ایمن ایستالکتریک از همسایگی سایت های یک و دو نیپکو و افزایش فضای شرکت ایمن ایستا جهت رفع کمبود فضای انبارش | N12: مدیریت سازمان /مدیرعامل ایمن ایستا /مدیران سایتهای نیپکو | O12: 1405/12
B16: مسایل خارجی | C16: با توجه به ادامه تحریم ها و مشکلات موجود در صنعت به ویژه صنعت خودرو ، هنوز مشکل عدم تامین نقدینگی مشتریان وجود دارد | K16: توجه به فروش After Market | N16: شرکت نورایستا خراسان | O16: پیوسته
K17: از طریق جذب محصولات جدید | N17: تحقیق و توسعه/فروش | O17: پیوسته
K18: از طریق اخذ گرید A | N18: CFT/MD | O18: 1405
C19: حذف برخی از خودروها(پارس-تیبا-ساینا) از چرخه تولید و نتیجتا حذف برخی از محصولات تولیدی شرکت | K19: افزایش پروژه ها و جایگزینی محصولات حذف شده | N19: تحقیق و توسعه/فروش | O19: پیوسته
C20: ورود به بازار بورس | K20: انجام شده است | N20: مالی | O20: 1405/04
A21: رضایت مشتری خارجی | B21: ساپکو | C21: 100 | D21: 80 | E21: 89.5 | F21: 90.4 | N21: فروش | O21: 1405/05
B22: سازه گستر | C22: 100 | D22: 80 | E22: 98 | F22: 91
A23: رضایت ذینفعان | B23: سهامداران سهامی عام /بورس | C23: با توجه به تعهدات سال 1404 سازمان به سهامداران و برگزاری مجمع ، تعهدات تعیین شده محقق شده است. | N23: مدیریت | O23: پیوسته
B24: کارکنان | C24: به هر یک از پرسنل شرکت تعداد 300 سهم بصورت پاداش واگذار شد. | N24: مدیریت
B25: جامعه عام | C25: چرخه محیط زیست محصول با استاندارد ISO 140001 ، مسئولیت اجتماعی در راستای اشتغالزایی و ارائه سهام برای خرید عموم | N25: تضمین کیفیت/مهندسی
B26: جامعه خاص | C26: در حوزه اداره کار، بیمه ، مالیات ، شهرداری ، شهرکهای صنعتی و محیط زیست مشکلی وجود نداشته است | N26: منابع
A27: میزان برآورده شدن دستیابی به اهداف کلان | C27: 100 | D27: 70 | E27: 76.23 | F27: 91 | N27: مدیریت
A28: شماره فرم : MA-F-19 | D28: شماره بروزرسانی : 0 | J28: تاریخ بروز رسانی : 99/05/10

Sheet 0
A40: امضاء مدیرعامل
